Workbook

Sheet summary
P1: Score | Q1: Level
K2: ='Group risk assessment L0'!A2 -> 0 | P2: ='Group risk assessment L0'!#REF! -> #REF! | Q2: =IF(P2>0.25, IF(P2>0.5,IF(P2>0.75,3,2),1),0) -> #REF! | R2: =IF(Q2=1,L$17,IF(Q2=2,L$18,IF(Q2=3,L$19,L$16))) -> #REF!
K3: =#REF! -> #REF! | P3: =#REF! -> #REF! | Q3: =IF(P3>0.25, IF(P3>0.5,IF(P3>0.75,3,2),1),0) -> #REF! | R3: =IF(Q3=1,L$17,IF(Q3=2,L$18,IF(Q3=3,L$19,L$16))) -> #REF!
K4: =#REF! -> #REF! | P4: =#REF! -> #REF! | Q4: =IF(P4>0.25, IF(P4>0.5,IF(P4>0.75,3,2),1),0) -> #REF! | R4: =IF(Q4=1,L$17,IF(Q4=2,L$18,IF(Q4=3,L$19,L$16))) -> #REF!
K5: =#REF! -> #REF! | P5: =#REF! -> #REF! | Q5: =IF(P5>0.25, IF(P5>0.5,IF(P5>0.75,3,2),1),0) -> #REF! | R5: =IF(Q5=1,L$17,IF(Q5=2,L$18,IF(Q5=3,L$19,L$16))) -> #REF!
K6: =#REF! -> #REF! | P6: =#REF! -> #REF! | Q6: =IF(P6>0.25, IF(P6>0.5,IF(P6>0.75,3,2),1),0) -> #REF! | R6: =IF(Q6=1,L$17,IF(Q6=2,L$18,IF(Q6=3,L$19,L$16))) -> #REF!
K7: =#REF! -> #REF! | P7: =#REF! -> #REF! | Q7: =IF(P7>0.25, IF(P7>0.5,IF(P7>0.75,3,2),1),0) -> #REF! | R7: =IF(Q7=1,L$17,IF(Q7=2,L$18,IF(Q7=3,L$19,L$16))) -> #REF!
K8: =#REF! -> #REF! | P8: =#REF! -> #REF! | Q8: =IF(P8>0.25, IF(P8>0.5,IF(P8>0.75,3,2),1),0) -> #REF! | R8: =IF(Q8=1,L$17,IF(Q8=2,L$18,IF(Q8=3,L$19,L$16))) -> #REF!
K9: =#REF! -> #REF! | P9: =#REF! -> #REF! | Q9: =IF(P9>0.25, IF(P9>0.5,IF(P9>0.75,3,2),1),0) -> #REF! | R9: =IF(Q9=1,L$17,IF(Q9=2,L$18,IF(Q9=3,L$19,L$16))) -> #REF!
K10: =#REF! -> #REF! | P10: =#REF! -> #REF! | Q10: =IF(P10>0.25, IF(P10>0.5,IF(P10>0.75,3,2),1),0) -> #REF! | R10: =IF(Q10=1,L$17,IF(Q10=2,L$18,IF(Q10=3,L$19,L$16))) -> #REF!
K11: =#REF! -> #REF! | P11: =#REF! -> #REF! | Q11: =IF(P11>0.25, IF(P11>0.5,IF(P11>0.75,3,2),1),0) -> #REF! | R11: =IF(Q11=1,L$17,IF(Q11=2,L$18,IF(Q11=3,L$19,L$16))) -> #REF!
P12: =AVERAGE(P2:P11) -> #REF! | Q12: =IF(P12>0.25, IF(P12>0.5,IF(P12>0.75,3,2),1),0) -> #REF! | R12: =IF(Q12=1,L$17,IF(Q12=2,L$18,IF(Q12=3,L$19,L$16))) -> #REF!
K15: Level
K16: 0 | L16: 0
K17: 1 | L17: ¬
K18: 2 | L18: ¬¬
K19: 3 | L19: ¬¬¬

Sheet NEW integrated RA (S + L)
A2: Question | B2: Requirements in standard | C2: Which CH type does this apply to? | D2: Other variables | E2: Issue | F2: Mitigation self-assessment – risk questions | G2: Answer parameter | H2: Country/sector risk context applicability | I2: Mitigation actions to be included in the Management Plan | J2: Comments
B3: Management
A4: 1 | C4: Group Certification | E4: Deforestation/ Native vegetation | F4: Do you expect production sites of group members to be shifting or expanding? | G4: no | H4: All | I4: No additional action needed
C5: Group Certification | E5: Deforestation/ Native vegetation | G5: Yes | H5: All | I5: Ensure that producers and workers know that natural vegetation and natural ecosystems have to be maintained, through awareness raising and regular monitoring. Clearly mark the boundaries of on-farm natural ecosystems and their buffer zones and ensure that production and processing activities, including agrochemical use, do not encroach into these areas. | J5: AP: not sure if this question is needed - mitigation measures are basically implementing th standard on the new farm units. They will anyway have to implement the whole standard, not only the criteria related to native vegetation RR: I think it is good to keep, to assess the risks of expanding to new areas
C6: Large | E6: Deforestation/ Native vegetation | F6: Are production sites shifting or expanding? | G6: no | H6: All | I6: No additional action needed
C7: Large | E7: Deforestation/ Native vegetation | G7: Yes | H7: All | I7: Ensure that workers know that natural vegetation and natural ecosystems have to be maintained, through awareness raising and regular monitoring. Clearly mark the boundaries of on-farm natural ecosystems and their buffer zones and ensure that production and processing activities, including agrochemical use, do not encroach into these areas. | J7: AP: not sure if this question is needed - mitigation measures are basically implementing th standard on the new farm units. They will anyway have to implement the whole standard, not only the criteria related to native vegetation
A8: 2 | B8: 1.8 Traceability | C8: Group Certification | E8: Intermediaries | F8: Do you/will you make use of intermediaries and/or subcontractors* in your supply chain? | G8: yes | H8: All | I8: Set up a clear traceability flow, that includes the documented and physical traceability rules for all actors in your supply chain (farmers, subcontractors, intermediary, processing units, transport, collection centers, management etc.). Train all actors on your traceability procedure. This includes the intermediaries and/or subcontractors. Monitor traceability and record keeping at all actors. Monitoring intermediaries especially during the harvest period. For monitoring, verify calibration of scales and record keeping at intermediaries and cross-check with information of sales from a sample of producers.
C9: Group Certification | E9: Intermediaries | G9: no | H9: All | I9: Set up a clear traceability flow, that includes the documented and physical traceability rules for all actors in your supply chain (farmers, processing units, transport, collection centers, management etc.). Train all actors on your traceability procedure. Monitor traceability and record keeping at all actors.
C10: Large | E10: Subcontractors | F10: Do you/will you make use of subcontractors* in your supply chain? | G10: yes | H10: All | I10: Set up a clear traceability flow, that includes the documented and physical traceability rules for all actors in your supply chain (processing units, transport, subcontractors, warehouse etc.). Train all actors on your traceability procedure. Monitor traceability and record keeping at all actors. For subcontractors, verifying if all subcontractors comply with the traceability procedure and all requirements in the standard that apply to them is part of the self-assessment.
C11: Large | E11: Subcontractors | G11: No | H11: All | I11: Set up a clear traceability flow, that includes the documented and physical traceability rules for all actors in your supply chain (processing units, transport, subcontractors, warehouse etc.). Train all actors on your traceability procedure. Monitor traceability and record keeping at all actors.
A12: 3 | C12: Group Certification | E12: Record keeping | F12: Do you expect farmers to have difficulties keeping (traceability) records? | G12: yes | H12: All | I12: Include administrion/keeping of receipts in training plan. The group supports the farmer to keep the receipts at the same place (ex: plastic folder) Put up signs to encourage farmers to keep receipts Monitor keeping of receipts | J12: AP: Do we mean records or receipts that they receive from the buying station/group? In the standard, farmers are not requested to keep records so not sure if 'record books' is needed. If receipt, then - the group needs to find a system for the farmer to keep them at the same place (ex: plastic folder) - remove the term 'record' to align with the standard and avoid confusion Changed
C13: Group Certification | E13: Record keeping | G13: no | H13: All | I13: No additional action needed
A14: 4 | C14: Group Certification | E14: Product separation | F14: Do you/will you only handle RA certified product and only buy from RA certified producers? | G14: yes | H14: All | I14: No further actions needed (apart from actions on compliance with the standard)
C15: Group Certification | E15: Product separation | F15: Do you/will you only handle RA certified product and only buy from RA certified producers? | G15: no | H15: All | I15: Implement a system for identifying the products originating from certified producers by means of physical or visual identification and in the tracebaility documents (receipts, registry, etc.). Example of visual identification can be tags on the bags during the product transportation and storage
A16: 5 | C16: Group Certification | E16: Record keeping | F16: Do group members have access to different market outlets / different buyers for their certifiers product? | G16: yes | H16: All | I16: Information on harvested volumes based on deliveries might not be reliable, therefore, put a system in place to get information on harvested volumes (this can be done by asking producers directly through out the year or during internal inspections). Collect the information on harvested volume throughout the year (monthly basis) instead of once a year during internal inspections | J16: AP: I would focus the mitigation action on getting the information on harvested volume through out the year (monthly basis) instead of once a year during internal inspections Changed
C17: Group Certification | E17: Record keeping | G17: no | H17: All | I17: No additional action needed | J17: Anneke: how can you reduce this risk?
A18: 6 | C18: Group Certification | E18: Product separation | F18: Do group members often rely on farm operators to manage their farm? | G18: yes | H18: all | I18: Guarantee that the farm manager is the same year after year through the internal inspections and that they are aware of the traceability requirements. Check if farm operator also manages non-certified farms and if so, encourage to include them in the certified group as well. Always invite the farm operator to trainings (on traceability and other topics) | J18: AP: mitigation action could be to always invite the farm operator to trainings (on traceability and other topics), unless already in the standard Changed
C19: Group Certification | E19: Product separation | G19: no | H19: All | I19: No additional action needed | J19: Anneke: not the right place to put it in the risk assessment?
A20: 7 | B20: Productivity & profitability | C20: Group Certification | E20: Optimum yield | F20: Is the average yield of the certified crop of the group members at or above the average yield for the crop in your country? | G20: Yes | H20: All | I20: No additional action needed | J20: AP: is a definition of 'optimum yield' needed? RR: Changed the formulation of the question
C21: Group Certification | E21: Optmimum yield | G21: No/Don't know | H21: All | I21: Train staff to recognise & prioritise production constraints in field Identify the main productivity constraints in the field Establish trials and business model farms to showcase impact of rejuvenation, fertilisation and good pest and disease control | J21: AP: production or productivity constraints? RR: productivity, so also costs of production
A22: 8 | C22: Group Certification | E22: Access to inputs and knowledge | F22: Do all group members have access to agricultural inputs and adequate knowledge to optimize productivity? | G22: Yes | H22: All | I22: No additional action needed
C23: Group Certification | E23: Access to inputs and knowledge | G23: No/Don't know | H23: All | I23: Identify the main needs among group members regarding inputs and knowledge. Support group members with training on finance, business management and understanding production costs and net income (self-selected requirement 1.4.5) If needed, facilitate accesss to financial services (e.g. loans for farm investments) (self-selected requirement 1.4.5)
A24: 9 | C24: Group Certification | E24: Living income | F24: Do you estimate that all group members earn a decent income with the production of the certified crop? | G24: Yes | H24: All | I24: No additional action needed
C25: Group Certification | E25: Living income | G25: No/Don't know | H25: All | I25: Assess the total net income for a representative sample of group member households, using the Living Income benchmark (self-selected requirement 1.9.6) Support group members with training on finance, business management and understanding production costs and net income (self-selected requirement 1.4.5) If needed, facilitate accesss to financial services (e.g. loans for farm investments) (self-selected requirement 1.4.5) Support group members to make informed decisions on income diversification strategies, e.g. other income generating activities, product upgrading (self-selected requirement 1.4.6)
B26: Farming practices
A27: 10 | B27: 2.6 Agrochemical management | C27: Group Certification | D27: Pesticides use | E27: Use of prohibited agrochemicals | F27: Review the Agrochemicals Rainforest Alliance Prohibited List : Is it common practice in the region to use one or more of the agrochemicals from the Rainforest Alliance Prohibited List, including on the non-certified crops on the farm? | G27: Yes | H27: All | I27: In case use of banned pesticide use is found during the external audit, the CB may issue a non-certification. To avoid this, include in your management plan: Group member training on the prohibition of the use of banned agrochemicals, and which ones those are. Group members training on the risk of using highly hazardous agrochemicals. Verify use of banned agrochemicals in internal inspections. Monitoring of use of agrochemicals during application period. Set up system to collect stocks of banned agrochemicals from the group members. Note: farmers that have used banned agrochemicals for the harvest to be certified cannot be included in the certification and have to wait for the next harvest cycle to apply again. | J27: AP: I would separate the 2 questions, answering a Yes/No is confusing here. Changed
C28: Group Certification | D28: Pesticides use | E28: Use of prohibited agrochemicals | G28: no | H28: All | I28: No additional action needed
B29: 2.6 Agrochemical management | C29: Large | D29: Pesticides use | E29: Use of prohibited agrochemicals | F29: Review the Agrochemicals Rainforest Alliance Prohibited List : do you use one or more of the agrochemicals from the Rainforest Alliance Prohibited List, including on the non-certified crops on the farm? | G29: Yes | H29: All | I29: In case use of prohibited pesticide use is found during the external audit, the CB may issue a non-certification. Farms that have used pesticides agrochemicals for the harvest to be certified cannot be included in the certification and have to wait for the next harvest cycle to apply again. If you haven't, then ensure ban of use of prohibited agrochemicals by implementing: Get rid of all prohibited agrochemicals prohibited agrochemicals, and which ones those are. Staff training on the risk of using highly hazardous agrochemicals. Verify use of prohibited agrochemicals in internal inspections. Monitoring of use of agrochemicals during application period.
C30: Large | D30: Pesticides use | E30: Use of prohibited agrochemicals | G30: no | H30: All | I30: No additional action needed
A31: 11 | B31: 2.6 Agrochemical management | C31: Group Certification | D31: Pesticides use | E31: Use of prohibited agrochemicals | F31: If you are certified by other standards, are there any RA banned agrochemicals that are not banned under these other standards? | G31: Yes | H31: All | I31: In case use of prohibited pesticide is found during the external audit, the CB may issue a non-certification. To avoid this, include in your management plan: Group member training on the ban of the use of prohibited agrochemicals, and which ones those are. Group members training on the risk of using highly hazardous agrochemicals. Verify use of prohibited agrochemicals in internal inspections. Monitoring of use of agrochemicals during application period. Set up system to collect stocks of prohibited agrochemicals from the group members. Note: farmers that have used prohibited agrochemicals for the harvest to be certified cannot be included in the certification and have to wait for the next harvest cycle to apply again. | J31: AP: I would separate the 2 questions, answering a Yes/No is confusing here. Changed
C32: Group Certification | D32: Pesticides use | E32: Use of prohibited agrochemicals | G32: no | H32: All | I32: No additional action needed
B33: 2.6 Agrochemical management | C33: Large | D33: Pesticides use | E33: Use of prohibited agrochemicals | F33: If you are certified by other standards, are there any Rainforest Alliance prohibited agrochemicals that are not banned under these other standards? | G33: Yes | H33: All | I33: In case use of prohibited pesticide use is found during the external audit, the CB may issue a non-certification. Farms that have used prohibited agrochemicals for the harvest to be certified cannot be included in the certification and have to wait for the next harvest cycle to apply again. If you haven't, then ensure ban of use of prohibited agrochemicals by implementing: Get rid of all prohibited agrochemicals. Staff training on the ban of the use of prohibited agrochemicals, and which ones those are. Staff training on the risk of using highly hazardous agrochemicals. Verify use of prohibited agrochemicals in internal inspections. Monitoring of use of agrochemicals during application period.
C34: Large | D34: Pesticides use | E34: Use of prohibited agrochemicals | G34: no | H34: All | I34: No additional action needed
A35: 12 | B35: 2.6 Agrochemical management | C35: Group Certification | D35: Pesticides use | E35: Amount of pesticide applications | F35: Is it common practice that producers firstly try biological, physical, and other non-chemical control methods for pest control before using agrochemicals? | G35: Yes | H35: All | I35: No additional action needed
C36: Group Certification | D36: Pesticides use | E36: Amount of pesticide applications | G36: No | H36: All | I36: Pay special attention to compliance with chapter 2.5 of the Agricultural Standard. In case needed, contact a local university or extension service for development of the Integrated Pest Management procedure. Identify sources for the purchase of lower toxicity agrochemicals as well as non-chemical pest control products. Make sure all members have the necessary knowledge and skills to apply Integrated Pest Management. Train members on record keeping. Monitor use of agrochemicals and application of IPM procedure by group members (including record keeping), during application time.
A37: 13 | C37: Group Certification | D37: Pesticides use | E37: Use of PPE | F37: Is it common practice that group members or their workers use Personal Protective Equipment (PPE) for application of agrochemicals? | G37: yes | H37: All | I37: No additional action needed | J37: AP: don't use the abbreviation PPE but the entire words I would rephrase 'Is it common practice that workers of group members use PPE for application of agrochemicals? ' to 'Is it common practice that group members or their workers use PPE for application of agrochemicals? Changed
C38: Group Certification | D38: Pesticides use | E38: Use of PPE | G38: no | H38: All | I38: Ensure availability of sufficient PPE for all those applying agrochemicals. Develop and implement management policies on the correct use of PPE. Make sure all those applying agrochemicals are trained on correct application of the agrochemicals and PPE. Group members trained on the risk of using highly hazardous agrochemicals. Explore the option of developing spray teams to replace agrochemical application by individual group members. Monitor the use of PPEs during application time. | J38: AP: Remove the part 'for group', this question will only populate for group certification Why 'training on banned agrochemicals' as a mitigation measure for this point? Changed
C39: Large | D39: Pesticides use | E39: Use of PPE | F39: Are all workers spraying agrochemicals using the correct Personal Protective Equipment (PPE) at all times when they apply agrochemicals? | G39: Yes | H39: All | I39: No additional action needed
C40: Large | D40: Pesticides use | E40: Use of PPE | G40: No | H40: All | I40: Make an assessment among the workers on the reasons for not using PPE. Use the outcomes of this assessment to define the measures. Develop and implement management policies on the correct use of PPE. Make sure all those applying agrochemicals are trained on correct application of the agrochemicals and PPE. Ensure availability of sufficient PPE for all those applying agrochemicals. Monitor the use of PPEs during application time.
A41: 14 | B41: 2.4 Soil conservation | C41: All | E41: Erosion | F41: Are there any areas that have a slope steeper than 1m rise over 3m run over an area >0.1ha? | G41: Yes | H41: All | I41: Implement measures to protect against erosion, including planting of native groundcover, contour planting, living barriers and drainage/dewatering systems.
...

Sheet Page de couverture
A1: Annexe S03 :
A2: Outil de Base d’Evaluation des Risques
A3: Document SA-S-SD-4a
A4: Version 1.3
A5: FR
A6: Traduction publiée le 11 may 2023
A7: Contraignant à partir du 1er juillet 2023
F9: Nom du document : | J9: Date de la première publication : | L9: Expire le :
F10: Annexe S03: Outil de Base d’Evaluation des Risques | J10: 6 février 2023 | L10: Jusqu’à nouvel ordre
F11: Lié à :
F12: SA-S-SD-1 Norme pour l’agriculture durable, exigences applicables aux exploitations agricoles SA-S-SD-2 Norme pour l’agriculture durable 2020 de Rainforest Alliance, exigences applicables à la chaîne d'approvisionnement SA-S-SD-23 Annexe Chapitre 5 : Social
O13: À propos de l’Annexe S03 : L’outil d’évaluation des risques contient les fichiers suivants :
O14: - SA-S-SD-4a Annexe S03: Outil de Base d’Evaluation des Risques - SA-S-SD-4b Annexe S03: Partie 1.3.5. Évaluation approfondie des risques de changement climatique - SA-S-SD-4c Annexe S03: Partie 1.6.3. Évaluation approfondie des risques liés au genre - SA-S-SD-4d Annexe S03: Partie 5.1.5 Évaluation approfondie et traitement des risques
F15: Remplace :
F16: SA-S-SD-4-V1.1FR Annexe S3 : Outil d’évaluation des risques
F17: Applicable aux :
F18: Titulaires de certificat
F19: Pays/Région :
F20: Tous
F21: Produit agricole : | J21: Type de certification :
F22: Tous les produits agricoles du champ d’application du système de certification de Rainforest Alliance ; veuillez voir les Règles pour la certification. | J22: Titulaires de certificat
F25: Décharge de responsabilité concernant la traduction
F26: Pour toute question liée à la signification précise des informations contenues dans la traduction, veuillez vous référer à la version officielle en anglais pour en obtenir la clarification. Toute divergence ou différence dans la signification engendrée par la traduction n’est pas contraignante et n’a pas d’effet sur la certification ou les audits.
A30: © 2023 Rainforest Alliance. Tous droits réservés. | F30: Plus d’informations ?
F31: Pour plus d’information sur Rainforest Alliance, visitez le site www.rainforest-alliance.org ou contactez info@ra.org
F33: Toute utilisation de ce contenu, y compris la reproduction, la modification, la distribution ou la republication, sans le consentement écrit préalable de Rainforest Alliance est strictement interdite.

Sheet Outil d’orientation pour l’éval

Sheet Overview and guidance
A2: Initial Risk Assessment
A3: Initial GAP assessment | B3: GAP assessment: the GAP assessment is an assessment of the GAPs between the current state of a Certificate Holder (estate or group) and the requirements of the Rainforest Allianca. This assessment is based on the Rainforest Alliance standard. This assessment is not mandatory, however will help you identify the areas that need to be worked on and the amount of work needed still to be ready for the certification audit.
A4: Self Assessment
A5: Mitigation Actions

Sheet Indiv. cert. Risk Assessment
B2: Chapter | C2: Theme | D2: Which farmers does this apply to? | E2: Issue | F2: Question applicable to (Group Management, medium/large estate management, group member during internal inspections) | G2: Mitigation self-assessment – risk questions | H2: Answer parameter | I2: Country/sector risk context applicability | J2: Mitigation actions to be included in the Management Plan | K2: Comments
B3: A. Management.
C4: Traceability | D4: All farm businesses | E4: Traceability procedure | F4: Management | G4: Do you/will you make use of intermediaries/subcontractors* in your supply chain? | H4: Yes | J4: Set up a clear traceability flow, that includes the documented and physical traceability rules for all actors (subcontractors/intermediary, processing units, CH management etc.). Train all actors on your traceability procedure. Monitor traceability and record keeping at intermediaries/subcontractors (during the harvest period). (Part of the Internal inspection (TBD))
C5: Traceability | D5: All farm businesses | E5: Traceability procedure | F5: Management | G5: Do you/will you make use of intermediaries/subcontractors* in your supply chain? | H5: No | J5: Set up a clear traceability flow, that includes the documented and physical traceability rules for all actors (farmer, collection centers, CH management).
B6: B. Farming Practices
C7: Inputs | D7: All farm businesses | F7: Management | G7: Review the Rainforest Alliance list of banned agrochemicals. Do you use one or more of the agrochemicals from the pesticide watchlist? | J7: Set up an IPM.
C8: Inputs | D8: All farm businesses | F8: Management | G8: (RR:) Are you applying pesticides more than XX times per year? (Define per crop what is an expected number of times to apply pesticides per year) | J8: Define strategy to reduce use of pesticides. Stress use of PPE. High risk for MRL.
A9: 1 | B9: 4. Environment | C9: Erosion | D9: All | E9: Steep Slopes | F9: All | G9: Are there any areas that have a slope greater than 1m rise over 3m run over an area >0.1ha? | H9: Yes | I9: All | J9: Implement measures to protect against erosion, including planting of native groundcover.
A10: 1 | B10: 4. Environment | C10: Erosion | D10: All | E10: Steep Slopes | F10: All | G10: Are there any areas that have a slope greater than 1m rise over 3m run over an area >0.1ha? | H10: No | I10: All | J10: No further action
B11: C. Working Conditions (social chapter or "workers and communities" which was our proposal)
C12: General | D12: There are 20 or more employees engaged at any point during the growing season | E12: Structure | G12: Does the farm have a trained committee/person in charge of the work around Assess and Address within the RA Standard? Is there a trained Grievance Committee (criterion 1.5)? Is there a trained Gender Committee (1.6)? | H12: Yes | I12: All | J12: No further action
C13: General | D13: There are 20 or more employees engaged at any point during the growing season | E13: Structure | G13: Does the farm have a trained committee/person in charge of the work around Assess and Address within the RA Standard? Is there a trained Grievance Committee (criterion 1.5)? Is there a trained Gender Committee (1.6)? | H13: No [to any] | I13: all | J13: Committee/person are (s)elected and committee set up; they participate in the A&A online training module / gender online training module and / or grievance mechanism training module as applicable ensuring all committees are set up and trained.
C14: General | D14: There are 20 or more employees engaged at any point during the growing season | E14: Skills/ capabilities | G14: Have supervisors and management experience / knowledge on dealing with cases of child labour, forced labour, discrimination and workplace violence/harassment? | H14: Yes | J14: No further actions
C15: General | D15: There are 20 or more employees engaged at any point during the growing season | E15: Skills/ capabilities | G15: Have supervisors and management experience / knowledge in dealing with cases of child labour, forced labour, discrimination and workplace violence/harassment? | H15: No | I15: All | J15: Management representatives / supervisors undergo training on assess and address topics
C16: General | D16: There are 20 or more employees engaged at any point during the growing season | E16: Public communication about Grievance Mechanism and Assess and Address Committee and its responsibilities | G16: Is information about the grievance mechanism and the assess and address committee visible and accessible to all workers? | H16: Yes | I16: All | J16: Check & update public display regularly to make sure information is still correct, visible and accessible to all; including languages of local and temporary staff
C17: General | D17: There are 20 or more employees engaged at any point during the growing season | E17: Public communication about Grievance Mechanism and Assess and Address Committee and its responsibilities | G17: Is information about the grievance mechanism and the assess and address committee visible and accessible to all workers? | H17: No | I17: All | J17: Ensure that producers and workers have access to practical information in their language about how and where they can access the grievance mechanism and the assess and address committee when they have a grievance that they want to be resolved.
C18: Discrimination | D18: All farm businesses | E18: Prevention of discrimination | G18: Do hiring procedures follow rules and regulations to prevent discriminatory practices? | H18: yes | I18: All | J18: No further actions
C19: Discrimination | D19: All farm businesses | E19: Prevention of discrimination | G19: Do hiring procedures follow rules and regulations to prevent discriminatory practices? | H19: No | I19: Low | J19: - Make sure all job vacancies are announced widely, in appropriate languages
C20: Discrimination | D20: All farm businesses | E20: Prevention of discrimination | G20: Do hiring procedures follow rules and regulations to prevent discriminatory practices? | H20: No | I20: Medium, High | J20: - Conduct in-person training of managers and supervisors on unconscious bias and on avoiding any kind of discriminatory decision in relation to hiring, working conditions, pay, benefits, training, promotion, termination, redundancy - develop procedures to prevent discrimination during hiring, between others: organize job interviews with more than one interviewer, preferibly of different genders; widespread announcement of job vacancies in appropriate languages; job description should not exclude certain groups of people
C21: Discrimination | D21: All farm businesses | E21: Equal opportunities & prevention of discrimination | G21: If any of the following groups are present at the farm, have you taken actions to fairly represent them amongst management and supervisory staff? These groups could include: -Women -> will go to gender requirement -Migrants (foreign or from within the country) - Specific ethnic minority groups (any ethnicities which are not the largest ethnicity within the workforce) -Indigenous groups (where applicable) -Groups whose members do not speak the dominant language in the country & region | H21: Yes | I21: All | J21: No further action
C22: Discrimination | D22: All farm businesses | E22: Equal opportunities & prevention of discrimination | G22: If any of the following groups are present at the farm, have you taken actions to fairly represent them amongst management and supervisory staff? These groups could include: -Women -> will go to gender requirement -Migrants (foreign or from within the country) - Specific ethnic minority groups (any ethnicities which are not the largest ethnicity within the workforce) -Indigenous groups (where applicable) -Groups whose members do not speak the dominant language in the country & region | H22: No | I22: Low | J22: publish vacancies for management and supervisory functions in a language(s) and in places accessible for all
C23: Discrimination | D23: All farm businesses | E23: Equal opportunities & prevention of discrimination | G23: If any of the following groups are present at the farm, have you taken actions to fairly represent them amongst management and supervisory staff? These groups could include: -Women -> will go to gender requirement -Migrants (foreign or from within the country) - Specific ethnic minority groups (any ethnicities which are not the largest ethnicity within the workforce) -Indigenous groups (where applicable) -Groups whose members do not speak the dominant language in the country & region | H23: No | I23: Medium, High | J23: - include unconscious bias and other anti discriminatory practices in the training and awareness raising of staff and management as required in 3.1.1 AND - publish vacancies for management and supervisory functions in a language(s) and in places accessible for all
C24: Workplace Violence and Harassment | D24: All farm businesses | E24: Workplace Violence and Harassment | G24: Has management taken any targeted action to prevent workplace violence and harassment (including sexual harassment)? | H24: Yes | I24: All | J24: No further action
C25: Workplace Violence and Harassment | D25: All farm businesses | E25: Workplace Violence and Harassment | G25: Has management taken any targeted action to prevent workplace violence and harassment (including sexual harassment)? | H25: No | I25: Low | J25: - do a risk scan of the workplace that will identify high risk areas (e.g. dark corridors, sections where people work on their own, etc.)
C26: Workplace Violence and Harassment | D26: All farm businesses | E26: Workplace Violence and Harassment | G26: Has management taken any targeted action to prevent workplace violence and harassment (including sexual harassment)? | H26: No | I26: Medium, High | J26: Implement at least one of the following measures: - Training for supervisors, safety guards and other staff in direct contact with workers on respectful behavior and concepts of workplace violence and harassment - training of workers on the topic on respectful behavior and concepts of workplace violence and harassment - do a risk scan of the workplace that will identify high risk areas and define actions to make them safer (e.g. dark corridors, sections where people work on their own, etc.) Please note: in most cases workplace violence and harassment will relate to experiences faced by women. However risks are also faced by men. Ensure your answers cover risks in relation to all workers regardless of gender.
... C46: Child labour | D46: All farm businesses | E46: Family workers | G46: Do workers bring their own children to the farm (to live or work)? | H46: No | I46: Lower | J46: No further action
C47: Forced labour | D47: All workplaces | E47: Labour providers | F47: Farm management | G47: Does the farm use labour providers to recruit any workers? | H47: No | I47: All | J47: No further action
C48: Forced labour | D48: All workplaces | E48: Labour providers | F48: Farm management | G48: Does the farm use labour providers to recruit any workers? | H48: Yes | I48: All | J48: 1. Farm must ensure that any labor providers used are licensed or certified by the appropriate government authority, if one exists.
C49: Forced labour | D49: All workplaces | E49: Labour providers | F49: Farm management | G49: Does the farm use labour providers to recruit any workers? | H49: Yes | I49: Med, High | J49: 1. Farms must have written contracts with each labor provider, requiring that labor providers abide by RA worker protection standards. 2. When possible, farms should directly contract workers who are recruited by labor providers. 3. For workers whose direct employer is a labor provider, the Assess & Address monitoring system should check periodically with some of these workers to ensure that their pay, working conditions, etc. are as promised by the labor provider. 4. Workers recruited through labor providers should be treated equally with other workers and provided the same information about their protections under the RA standard. 5. The Assess & Address monitoring system should periodically check with workers who are recruited through labor providers, to see if they owe any debts related to recruitment fees. If so, the farm should negotiate with the labor provider full repayment of these fees to the worker. 6. Management should assign responsibility to one or more members of staff to oversee labor providers' compliance and the above measures. Farms should stop working with labor recruiters that do not meet these expectations.
D50: All workplaces | E50: Wage payment practices | F50: Farm management | G50: Are workers paid by volume/piece rate? | H50: No | I50: All | J50: No further action.
C51: Forced labour | D51: All workplaces | E51: Wage payment practices | F51: Farm management | G51: Are workers paid by volume/piece rate? | H51: Yes | I51: All | J51: 1. Farms must ensure that workers have written or verbal contracts in place according to requirement 3.3.1. 2. When calculated by volume, workers' pay must equal at least the minimum wage based on a 48-hour working week or national legal working hours limit. 3. Deductions from wages for costs such as employer-provided housing or food must only be taken with workers' consent. 4. Workers must be paid at least monthly. 5. Workers must be provided pay slips showing hours worked (regular and overtime) and/or volume produced, calculation of wages and deductions, and wages paid.
D52: All workplaces | E52: Wage payment practices | F52: Farm management | G52: Are workers paid by volume/piece rate? | H52: Yes | I52: Med, High | J52: 1. Management should confirm that personnel responsible for wage payment are correctly trained in calculations and requirements. 2. Management should make available personnel who speak the appropriate languages to explain/answer workers' questions about wage calculations and pay slips. 3. Management should assign responsibility to a member of staff to conduct a periodic review of pay records to identify instances of underpayment, delayed payment, and other inconsistencies.
C53: Forced labour | D53: All workplaces | E53: Freedom of movement | F53: Farm management | G53: Are security guards present on the farm/group premises? | H53: No | I53: All | J53: No further action
C54: Forced labour | D54: All workplaces | E54: Freedom of movement | F54: Farm management | G54: Are security guards present on the farm/group premises? | H54: Yes | I54: All | J54: 1. Farms must communicate to workers of their rights under the law to freely leave the job. This can be done through their contracts, information posted in the workplace, a workers' organization, one of the farm's committees, or other means. 2. For workers living on the farm, farms should communicate their rights to freedom of movement on and off the farm outside working hours.
C55: Forced labour | D55: All workplaces | E55: Freedom of movement | F55: Farm management | G55: Are security guards present on the farm/group premises? | H55: Yes | I55: Med, High | J55: 1. The Assess & Address monitoring system, working with other committees such as the Gender Committee, should periodically check with workers to see if they feel threatened by security guards.
C56: Forced labour | D56: Non-local workers are included among the workforce How will we know this; is it a question in the registry? | E56: Prison/military labor | F56: Farm management | G56: Are any workers recruited/provided to the farm by military or prison officials? | H56: No | I56: All | J56: No further actions.
C57: Forced labour | D57: Non-local workers are included among the workforce How will we know this; is it a question in the registry? | E57: Prison/military labor | F57: Farm management | G57: Are any workers recruited/provided to the farm by military or prison officials? | H57: Yes | I57: All | J57: 1. Military officials mobilizing military personnel to perform agricultural labor is a form of forced labor. Farms must not utilize this type of labor. 2. Farms must ensure that any prisoners working on the farm have freely provided their consent to work. 3. Prison labor must be treated the same as all other workers with respect to contracts, pay, working conditions, and all other worker protections in the RA standard.
C58: Forced labour | D58: Non-local workers are included among the workforce How will we know this; is it a question in the registry? | E58: Prison/military labor | F58: Farm management | G58: Are any workers recruited/provided to the farm by military or prison officials? | H58: Yes | I58: Med, High | J58: 1. The Assess & Address monitoring system should periodically check with prison laborers to ensure they are receiving the same treatment as other workers.
C59: Forced labour | D59: Non-local workers are included among the workforce How will we know this; is it a question in the registry? | E59: Deposit or document retention | F59: Farm management | G59: Do workers give any money (such as deposits) or documents (such as passports) to farm management or labor providers? | H59: No | I59: All | J59: No further action.
C60: Forced labour | D60: Non-local workers are included among the workforce How will we know this; is it a question in the registry? | E60: Deposit or document retention | F60: Farm management | G60: Do workers give any money (such as deposits) or documents (such as passports) to farm management or labor providers? | H60: Yes | I60: All | J60: 1. Farms should not require workers to pay any type of deposit or provide any personal document to management, other than to confirm identity at the time of hiring.
...

Sheet Risk assessment l1
A2: Initial Risk Assessment: the initial risk assessment is a set of questions a group or estate management shall answer before implementation of the certification program in order to have an indication on topics that require special attendion during planning and implementation of the program. E.g. topics that need to be covered in the trainings, topics that require special attention during internal inspections etc. -What topics do we want to include in the initial risk assessment? -Who can provide the questions per topic?
B5: Requirement | D5: Feeds into: internal inspections | E5: High/Medium/Low | F5: Feeds into: management plan | I5: Level 0 | J5: Level 1 | K5: Level 2 | L5: Level 3
B6: (1.3.5) Management conducts a risk assessment in relation to the criteria in this standard for their group/farm at least every three years, including at least the risks associated with: -Traceability - Social risks including child labor, forced labor and workplace harassment and violence - Agrochemicals management - Deforestation and biodiversity loss - Economic fluctuations or shocks - Climate change, extreme weather, environmental hazards | D6: (1.3.1) An internal inspection system is in place to assess compliance of group members with the Rainforest Alliance standard. ... - consecutive years: - scope of inspection is based on risk assessment and on previous inspections | F6: (1.4.1) Management makes a management plan, describing improvement areas, actions to be taken, services to be delivered and usage of Premium. The management plan is based on at least, but not limited to, the internal inspection (1.3.1) and risk assessment (1.3.5). Actions are implemented, monitored, and documented. The management plan is updated at least every three years. | I6: No PDCA: Lack of documentation (processes and policies). No structure or formalized organization. | J6: Reactive, but documented (PDCA): Documentation exists with an informal structure implementing the processes and policies. Implementation occurs in reaction to the system, as no planning was taken into account when policies and process were developed. | K6: Proactive (PDCA): Formal documentation and structure to implement policies and processes, stakeholder involvement and planning has been involved during the development of the policies and processes. Post-implementation, there was a lack of evaluation and learning. | L6: Continuous improvement (PDCA): Formal documentation and structure to implement policies and processes, stakeholder involvement and planning has been involved during the development of the policies and processes. Post-implementation, activities were checked, evaluated and monitored to ensure that learning and improvement takes place. | M6: This page has:
M7: =COUNTA(N9:N64) -> 13
A8: A. Management (see capacity assessment tool?) | C8: Topic | D8: Question applicable to (Group Managemet, medium/large estate management, group member during internal inspections) | F8: Question | G8: Yes/No | H8: If yes, should show in Mitigation Actions | M8: Supporting documents / evidence: | N8: Selection | O8: Weighted | P8: =AVERAGE(P9:P64) -> 0.38430769 | Q8: Maximum
A9: A. | B9: 1 | C9: Group management capacity
N10: 4 | O10: =IF(N10=1,0)+IF(N10=2,0.333)+IF(N10=3,0.666)+IF(N10=4,100%) -> 1 | P10: =O10*Q10/100 -> 1 | Q10: 100
A11: A. | B11: 2 | C11: Economic fluctuations or shocks
A12: A. | B12: 3 | C12: Traceability | D12: CH management | F12: Do you/will you make use of intermediaries in your supply chain? | H12: Set up a clear traceability flow, that includes the documented and physical traceability rules for all actors (farmer, intermediary, CH management). Train the intermediaries on traceability. Monitor traicability and record keeping at intermediaries (during the harvest period).
A13: B. Farming Practices | M13: Supporting documents / evidence: | N13: Selection | O13: Weighted | P13: =AVERAGE(P14:P71) -> 0.333 | Q13: Maximum
A14: B. | B14: 4 | C14: Agrochemical management | D14: Farm level | F14: Review the Rainforest Alliance list of banned agrochemicals. Is it common practice in the region to use one or more of the agrochemicals from the banned pesticide list? | H14: Group member training on the prohibition of the use of banned agrochemicals, and which ones those are. Include verification on use of banned agrochemicals in internal inspections. Monitoring of use of banned agrochemicals during application period. Note: farmers that have used banned agrochemicals for the harvest to be certified cannot be included in the certification and have to wait for the next harvest cycle to apply again.
A15: B. | B15: 5
N16: 2 | O16: =IF(N16=1,0)+IF(N16=2,0.333)+IF(N16=3,0.666)+IF(N16=4,100%) -> 0.333 | P16: =O16*Q16/100 -> 0.333 | Q16: 100
A17: B. | B17: 6
N18: 2 | O18: =IF(N18=1,0)+IF(N18=2,0.333)+IF(N18=3,0.666)+IF(N18=4,100%) -> 0.333 | P18: =O18*Q18/100 -> 0.333 | Q18: 100
A19: C. Working Conditions | M19: Supporting documents / evidence: | N19: Selection | O19: Weighted | P19: =AVERAGE(P20:P78) -> 0.333 | Q19: Maximum
A20: C. | B20: 7 | C20: Discrimination | D20: Group members | F20: If you hire labor (beyond family labor), are any of the workers from historically discriminated groups (indigenous communities, minorities, lower castes etc.)? | H20: Ensure that all workers receive equal pay for jobs of equal value. Ensure that all workers understand the working conditions if needed by explaining in their own language.
D21: Group members | F21: Is it possible that any of the group members hires labor (beyond family labor), are any of the workers from historically discriminated groups (indigenous communities, minorities, lower castes etc.)?
D22: CH management | F22: Do you have any female workers beyond family labor? | H22: Ensure that a registry is kept, also if they are casual workers, indicating their sex. Ensure that they understand the working conditions, including remuneration level and other benefits, if needed by explaining in their own language.
D23: Group members | F23: Is it possible that any of the group members hires any female workers beyond family labor?
A24: C. | B24: 8 | C24: Forced Labor | D24: Group members | F24: Is it possible that there migrant workers (including seasonal and temporary) working on any of the farms? | H24: Ensure that migrant workers have safe place to keep their identity and other important documents, which is accessible to them at all times.
D25: Group members | F25: Is it possible that there are workers on any of the farms who were recruited by a third-party labor provider? | H25: Maintain records of which workers were recruited by which labor provider. Ensure that written contracts are in place between the farm/group and each labor provider, specifying that providers must abide by all Rainforest Alliance standards and that the workers they recruit must not pay any recruitment fees. Ensure that workers are always paid their wages directly, not indirectly through a third party.
D26: Group members | F26: Is it possible that workers on any of the farms have paid a recruitment fee to labor providers or other actors in the recruitment chain? | H26: In the hiring process, integrate a process to ask workers whether they hold any recruitment-related debt.
D27: Group members | F27: Is it possible that any workers are lacking a written contract, or documented verbal agreement? | H27: Group members work towards signing direct contracts/verbal agreements with permanent workers and workers who are employed for more than 3 consecutive months.
D28: Group members | F28: Is it possible that any workers are directly employed by labor providers (contract signed between worker and labor provider)? | H28: Group members work towards signing direct contracts/verbal agreements with permanent workers and workers who are employed for more than 3 consecutive months.
D29: Group members | F29: Do hired workers receive food, housing, and/or transportation provided by the farmer/group management? | H29: Ensure that workers' contracts/records of verbal agreements specify the in-kind benefits they will receive and specific cost deductions that will be taken for them. In-kind benefits must be in accordance with national law, and never exceed 30% of the total remuneration.
D30: Group members | F30: @Lennie: It would. But isn't that OK? If this tool helps a farmer identify an actual gap, it also helps the farmer remediate that gap. | H30: Eliminate any restrictions on workers' freedom of movement outside their working hours. Allow workers to maintain possession of their mobile phones and other communication devices.
D31: Group members | F31: Do workers ever wait longer than 1 month to be paid? | H31: Ensure that workers are paid regularly at scheduled intervals, at least monthly. Payments must be documented with a pay slip or other suitable wage record to allow verification.
D32: Group members | F32: Do workers ever receive advances or loans from the farm/group? | H32: Ensure that advances/loans amount to no more than 1-2 months' salary and that repayment terms are reasonable (no higher than prevailing market interest rates), documented, and agreed by both parties. | N32: 2 | O32: =IF(N32=1,0)+IF(N32=2,0.333)+IF(N32=3,0.666)+IF(N32=4,100%) -> 0.333 | P32: =O32*Q32/100 -> 0.333 | Q32: 100
A33: C. | B33: 9 | C33: Child Labor | F33: Is pre-school education and/or day care freely available for children in this community? | H33: Check if pre-school age children are taken on to farms and if so, if there is a safe place for them to be.
H34: Talk to parents and guardings about risk of children being on farms and work with farm owners and local organisations to find suitable and safe places for children to be when parent’s work.
F35: Does this community lack sufficient primary and secondary schools to educate all children? | H35: As a longer-term measure, engage with external actors to obtain support to improve school access.
F36: If there are schools in the community, do they charge any formal or informal fees to enroll children, or are there costs associated with education including books, uniform, transport, etc.? | H36: As a longer-term measure, engage with external actors to obtain support for children whose families cannot afford these costs.
F37: If schools are available in the community, do parents keep children home from school in order to work or do household tasks; and/or do older children drop out of school to work? | H37: Raise awareness among workers/members/families of the importance of sending children to school and the Rainforest Alliance requirement against child labor.
F38: Is it considered normal in this community for children to work in farming? | H38: Raise awareness among workers/members/families of the importance of sending children to school and the Rainforest Alliance requirement against child labor. | N38: 2 | O38: =IF(N38=1,0)+IF(N38=2,0.333)+IF(N38=3,0.666)+IF(N38=4,100%) -> 0.333 | P38: =O38*Q38/100 -> 0.333 | Q38: 100
A39: C. | B39: 10 | C39: Harassement and Violence | F39: If you hire labor (beyond family labor), are there female workers between them who work without the presence of their partner or another relative who work with male workers? | H39: Ensure that female workers work together, if possible, with a female supervisor.
F40: If you hire labor (beyond family labor), are there young workers (below 21) who work without the presence of a family member? | H40: Ensure that young workers work in a safe environment, in a group, if possible with a female supervisor.
F41: Do you have female and/or young workers amongst your hired labor (beyond family labor) who work in an isolated environment? | H41: Ensure that they work in groups with at least several women, if possible with a female supervisor.
F42: Have all supervisors been trained on appropriate behavior and the procedures that are in place to address inappropriate behavior towards other workers? | H42: Company supervisors are trained to use appropriate disciplinary techniques and procedures. A policy is in place to suspend or terminate supervisors who do not adhere to these techniques and procedures.
F43: Does the farm/group hire security guards to protect the premises? | H43: Ensure that workers are able to come and go from the farm without intimidation from security guards. Train security guards on proper conduct including a prohibition on threats and bribery. | N43: 2 | O43: =IF(N43=1,0)+IF(N43=2,0.333)+IF(N43=3,0.666)+IF(N43=4,100%) -> 0.333 | P43: =O43*Q43/100 -> 0.333 | Q43: 100
...

Sheet Sheet2
A1: Main aspects based on AMEA guidelines:
A2: A. Organizational purpose and Governance practices
A3: B. Business management
A4: C. Member engagement and planning
A5: D. Human resource management
A6: E. Financial management
A7: F. Community and stakeholder engagement
A8: G. Member services and business activiies
A10: Red | B10: From the AMEA guidelines
A11: Yellow | B11: From the M4 tool
A12: Wit: | B12: From the NewForesight tool
A13: Beige: | B13: From the Adore tool

Sheet Group risk assessment L0
A1: Question | B1: Theme | C1: Certification option (group or large estate) | D1: Which CHs does this apply to? | E1: Issue | F1: Mitigation self-assessment – risk questions | G1: Answer parameter | H1: Country/sector risk context applicability | I1: Mitigation actions to be included in the Management Plan | J1: Comments
B2: Management
A3: 1 | B3: Group management capacity | C3: Group Certification | D3: All Farmer Groups | E3: Management capacity | F3: Based on the outcomes of the capacity assessment tool, have you identified areas to improve? If yes, please indicate which actions you want to take for the applicable areas of the 7 areas included in the Capacity Assessment Tool. | H3: All | I3: 1
C4: Group Certification | D4: All Farmer Groups | H4: All | I4: 2
C5: Group Certification | D5: All Farmer Groups | H5: All | I5: 3
C6: Group Certification | D6: All Farmer Groups | H6: All | I6: 4
C7: Group Certification | D7: All Farmer Groups | H7: All | I7: 5
C8: Group Certification | D8: All Farmer Groups | H8: All | I8: 6
C9: Group Certification | D9: All Farmer Groups | H9: All | I9: 7
A10: 1 | B10: Traceability | C10: Group Certification | D10: All Farmer Groups | E10: Intermediaries | F10: Do you/will you make use of intermediaries* in your supply chain? | G10: yes | H10: All | I10: Include all intermediaries in your traceability procedure. Train the intermediaries on traceability. Monitor traceability, calibration of scales and record keeping at intermediaries (during the harvest period) and cross-check with information of sales from a sample of producers. If intermediaires are paid according to weight bought in, mitigation should include regular verification of scales.
C11: Group Certification | D11: All Farmer Groups | E11: Intermediaries | F11: Do you/will you make use of intermediaries* in your supply chain? | G11: no | H11: All | I11: No further actions needed (apart from actions on compliance with the standard)
A12: 1 | C12: Group Certification | D12: All Farmer Groups | E12: Record keeping | F12: Do you expect farmers to have difficulties keeping (traceability) records? | G12: yes | H12: All | I12: Include record keeping in training plan. Monitor record keeping.
C13: Group Certification | D13: All Farmer Groups | E13: Record keeping | F13: Do you expect farmers to have difficulties keeping records? | G13: no | H13: All | I13: No further actions needed (apart from actions on compliance with the standard)
A14: 1 | C14: All farmer organizations | D14: All | E14: Product separation | F14: Do you/will you only handle RA certified product and only buy from RA certified producers? | G14: yes | H14: All | I14: No further actions needed (apart from actions on compliance with the standard)
C15: All farmer organizations | D15: All | E15: Product separation | F15: Do you/will you only handle RA certified product and only buy from RA certified producers? | G15: no | H15: All | I15: Implement a system for identifying the products originating from certified producers by means of physical or visual identification and in the tracebaility documents (receipts, registry, etc.).
A16: 1 | C16: Group Certification | D16: All Farmer Groups | E16: Yield estimation | F16: Is there an important pressure on the land? Do farmers often divide or sell their land? | G16: yes | H16: All | I16: Include assessment of the certified area for each producer in the yearly internal inspections to ensure that the areas in the group member administration match the reality of the farms.
C17: Group Certification | D17: All Farmer Groups | E17: Yield estimation | F17: Is there an important pressure on the land? Do farmers often divide or sell their land? | G17: no | H17: All | I17: No further actions needed (apart from actions on compliance with the standard)
A18: 1 | C18: Group Certification | D18: All Farmer Groups | E18: Record keeping | F18: Do group members have access to different market outlets / different buyers for their certifiers product? | G18: yes | H18: All | I18: Information on harvested volumes based on deliveries might not be reliable, therefore, put a system in place to get information on harvested volumes (this can be done by asking producers directly through out the year or during internal inspections).
C19: Group Certification | D19: All Farmer Groups | E19: Record keeping | F19: Do group members have access to different market outlets / different buyers for their certifiers product? | G19: no | H19: All | I19: No further actions needed (apart from actions on compliance with the standard)
A20: 1 | C20: Group Certification | D20: All Farmer Groups | E20: Product separation | F20: Do group members often rely on farm operators to manage their farm? | G20: yes | H20: all | I20: Guarantee that the farm managers is the same year after year through the internal inspections and that they are aware of the traceability requirements. Check if farm operator also manages non-certified farms and if so, encourage to include them in the certified group as well.
C21: Group Certification | D21: All Farmer Groups | E21: Product separation | F21: Do group members often rely on farm operators to manage their farm? | G21: no | H21: All | I21: No further actions needed (apart from actions on compliance with the standard)
A22: 1 | C22: All farmer organizations | D22: All | E22: Product separation | F22: Does the certified product need to be aggregated for processing? | G22: yes | H22: All | I22: Mixing with non-certified products might occur to guarantee minimum volume for processing. Group management to put a control system to regularly check that product separation is respected (also at subcontractor level).
