Workbook
Name Answer: '2. SAISIE DES DONNÉES'!$F$38
Name Answer_24a: '2. SAISIE DES DONNÉES'!$F$41
Name AnswerQ32: '2. SAISIE DES DONNÉES'!$F$54
Name First: '2. SAISIE DES DONNÉES'!$X$72:$Z$72
Name First_24a: '2. SAISIE DES DONNÉES'!$Y$64:$Z$64
Name FirstQ32: '2. SAISIE DES DONNÉES'!$Y$68:$AB$68
Name Second: INDEX(Selections_New,,MATCH(Answer,First,0))
Name Second: INDEX(Selections_New,,MATCH(Answer,First,0))
Name Second_24a: INDEX('2. SAISIE DES DONNÉES'!$Y$65:$Z$66,,MATCH(Answer_24a,First_24a,0))
Name Second_24a: INDEX('2. SAISIE DES DONNÉES'!$Y$65:$Z$66,,MATCH(Answer_24a,First_24a,0))
Name SecondQ33: INDEX(SelectionsQ33,,MATCH(AnswerQ32,FirstQ32,0))
Name SecondQ33: INDEX(SelectionsQ33,,MATCH(AnswerQ32,FirstQ32,0))
Name Selections_24a: '2. SAISIE DES DONNÉES'!$Y$64:$Z$66
Name Selections_New: '2. SAISIE DES DONNÉES'!$X$72:$Z$74
Name SelectionsQ33: '2. SAISIE DES DONNÉES'!$Y$68:$AB$70

Sheet Page de couverture
A1: Annexe S03 :
A2: Partie 1.3.5. Évaluation approfondie des risques du changement climatique
A3: Document SA-S-SD-4b
A4: Version 1.3
A5: Publié le 11 mai 2023
A6: Contraignant à partir du 1er juillet 2023
F7: Nom du document : | J7: Première publication : | L7: Expire le : | O7: À propos de l’Annexe S03 : L’outil d’évaluation des risques contient les fichiers suivants :
F8: Annexe S03 : Partie 1.3.5. Évaluation approfondie des risques du changement climatique | J8: 6 Février 2023 | L8: Jusqu’à nouvel ordre | O8: - SA-S-SD-4a Annexe S03 : Outil d’évaluation et d’atténuation des risques de base - SA-S-SD-4b Annexe S03 : Partie 1.3.5. Évaluation approfondie des risques de changement climatique - SA-S-SD-4c Annexe S03 : Partie 1.6.3. Évaluation - approfondie des risques liés au genre - SA-S-SD-4d Annexe S03 : Partie 5.1.5 Étude approfondie de l'évaluation-et-résolution des risques
F9: Lié à :
F10: SA-S-SD-1 Norme pour l’agriculture durable 2020 de Rainforest Alliance, Exigences pour les exploitations agricoles SA-S-SD-24 Annexe Chapitre 6 : Environnement
F13: Remplace :
F14: -
F15: Applicable aux :
F16: Titulaires d'un certificat
F17: Pays/Région :
F18: Tous
F19: Produit agricole : | J19: Type de certification : | O19: Limite de fonctionnalité
F20: Tous les produits agricoles entrant dans le champ d’application du système de certification de Rainforest Alliance ; veuillez voir les Règles de certification. | J20: Titulaires de certificats d’exploitations agricoles | O20: Pour être pleinement fonctionnel, cet outil nécessite Microsoft Excel 2013 ou des versions ultérieures. Avec les versions antérieures à Excel 2013, sa pleine fonctionnalité ne peut être garantie.
F22: Décharge de responsabilité concernant la traduction
F23: Pour toute question liée à la signification précise des informations contenues dans ce document traduit, veuillez vous référer à la version officielle en anglais pour en obtenir la clarification. Les divergences ou différences de sens constatées entre la traduction et le texte original ne sont pas contraignantes et sont sans effet sur la certification ou les audits.
F27: Plus d’informations ?
F28: Pour plus d’information sur Rainforest Alliance, visitez le site www.rainforest-alliance.org ou contactez info@ra.org
F32: Toute utilisation de ce contenu, y compris la reproduction, la modification, la distribution ou la réédition, sans l’accord préalable écrit de Rainforest Alliance est strictement interdite.
A33: © 2023 Rainforest Alliance. Tous droits réservés.

Sheet 1. DOCUMENT D’ORIENTATION
B2: RAINFOREST ALLIANCE -- OUTIL D’ÉVALUATION APPROFONDIE DES RISQUES DU CHANGEMENT CLIMATIQUE
B5: Page d’explication
B7: 1. Paramétrage de l’outil | D7: 2. Explication de l’onglet de saisie des données (n° 2) | F7: 3. Explication de l’onglet de résultats (n° 3)
B8: L’outil comprend trois onglets. Onglet n° 1 (document d'orientation), explication de l’outil et des différentes étapes nécessaires à la finalisation de l’évaluation des risques du changement climatique. | D8: ÉTAPE 1 Sélection du lieu, de la culture et de la langue. L’onglet de saisie des données vous permet de choisir la région (au niveau du continent), le pays et la sous-région éventuelle (à l’intérieur du pays). Il permet également de sélectionner les cultures (café, thé, bananes, cacao). | F8: Section 1. Vue d’ensemble du niveau de risque climatique. Cette section détermine le niveau de risque climatique sur la base de vos réponses aux questions de la section sur l’exposition et l’impact en onglet n° 2 (saisie des données).
B9: Onglet n° 2 (Saisie des données), qui permet de saisir les données (position, cultures et langue) et de répondre à des questions spécifiques sur les impacts climatique et l’exposition et sur votre capacité d’adaptation au changement climatique | D9: ÉTAPE 2. Répondre (par oui ou par non) aux questions relatives à votre niveau d’exposition aux impacts du changement climatique Vos réponses à 7 questions permettent de définir votre niveau d’exposition aux impacts du changement climatique. Répondez à ces question par « oui » ou par « non ». Sélectionnez la réponse dans la liste déroulante. | F9: Section 2. Vue d’ensemble de votre capacité d’adaptation et de votre niveau de résilience face aux impacts du changement climatique. Cette section permet d’établir une évaluation en forme de graphique en toile d'araignée qui représente votre résilience globale et votre capacité d’adaptation pour réagir au changement climatique. Les scores sont basés sur vos réponses à la section de capacité d’adaptation en onglet n° 2. La capacité d’adaptation porte sur les catégories exploitation, eau, sol, végétation naturelle et gestion des cultures. Ces évaluations vous permettent de découvrir les domaines à améliorer.
B10: Onglet n° 3 (Résultats) qui fournit les résultats de l’évaluation | D10: ÉTAPE 3. Répondre (par oui ou par non) aux questions relatives à votre niveau d’exposition aux impacts du changement climatique Vos réponses à 7 questions permettent de définir votre niveau d’exposition aux impacts du changement climatique. Répondez à ces question par « oui » ou par « non ». Sélectionnez la réponse dans la liste déroulante. | F10: Section 3. Mesures d’atténuation générale Sur la base des cultures que vous avez sélectionnées, vous recevez une liste de mesures d’atténuation que vous pouvez mettre en œuvre pour une meilleure adaptation au changement climatique. Cette liste contient les actions générales pour les quatre cultures différentes.
D11: ÉTAPE 4. Répondre (par oui ou par non) aux questions relatives à votre sensibilité aux impacts du changement climatique Série de questions qui permettent d’évaluer votre niveau d’adaptabilité aux impacts du changement climatique. Les questions de cette sections sont réparties entre les thèmes du sol, de l’eau, de la végétation naturelle et des caractéristiques spécifiques des récoltes.

Sheet 2. SAISIE DES DONNÉES
B2: SAISIE DES DONNÉES
B5: Sélection des cultures
B6: Sélectionnez une culture dans la liste déroulante→ | C6: [SÉLECTIONNER]
B9: Étape 2. Niveau d’exposition
C10: Question 1 | D10: =VLOOKUP($C$6&C10,'Data Sheet Current Vulnerabilit'!$D:$E,2,FALSE) -> #N/A | F10: [SÉLECTIONNER] | V10: =IF(F10=$V$65,-1)+IF(F10=$V$66,1) -> 0 | Z10: =SUM(V10:V25) -> 0
B11: Exposition : | C11: Question 2 | D11: =VLOOKUP($C$6&C11,'Data Sheet Current Vulnerabilit'!$D:$E,2,FALSE) -> #N/A | F11: [SÉLECTIONNER] | V11: =IF(F11=$V$65,-1)+IF(F11=$V$66,1) -> 0
B12: « nature et degré des changements climatiques auxquelles un système est exposé. » | C12: Question 3a | D12: =VLOOKUP($C$6&C12,'Data Sheet Current Vulnerabilit'!$D:$E,2,FALSE) -> #N/A | F12: [SÉLECTIONNER] | V12: =IF(F12=$V$65,-1)+IF(F12=$V$66,1) -> 0
C13: Question 3b | D13: =VLOOKUP($C$6&C13,'Data Sheet Current Vulnerabilit'!$D:$E,2,FALSE) -> #N/A | F13: [SÉLECTIONNER] | V13: =IF(F13=$V$65,-1)+IF(F13=$V$66,1) -> 0
C14: Question 4 | D14: =VLOOKUP($C$6&C14,'Data Sheet Current Vulnerabilit'!$D:$E,2,FALSE) -> #N/A | F14: [SÉLECTIONNER] | V14: =IF(F14=$V$65,-1)+IF(F14=$V$66,1) -> 0
C15: Question 5 | D15: =VLOOKUP($C$6&C15,'Data Sheet Current Vulnerabilit'!$D:$E,2,FALSE) -> #N/A | F15: [SÉLECTIONNER] | V15: =IF(F15=$V$65,-1)+IF(F15=$V$66,1) -> 0
C16: Question 6 | D16: =VLOOKUP($C$6&C16,'Data Sheet Current Vulnerabilit'!$D:$E,2,FALSE) -> #N/A | F16: [SÉLECTIONNER] | V16: =IF(F16=$V$65,-1)+IF(F16=$V$66,1) -> 0
B18: Étape 3. Niveau d’ Impact
C19: Question 7 | D19: =VLOOKUP($C$6&C19,'Data Sheet Current Vulnerabilit'!$D:$E,2,FALSE) -> #N/A | F19: [SÉLECTIONNER] | V19: =IF(F19=$V$65,-1)+IF(F19=$V$66,1) -> 0
C20: Question 8 | D20: =VLOOKUP($C$6&C20,'Data Sheet Current Vulnerabilit'!$D:$E,2,FALSE) -> #N/A | F20: [SÉLECTIONNER] | V20: =IF(F20=$V$65,-1)+IF(F20=$V$66,1) -> 0
B21: Impacts : | C21: Question 9 | D21: =VLOOKUP($C$6&C21,'Data Sheet Current Vulnerabilit'!$D:$E,2,FALSE) -> #N/A | F21: [SÉLECTIONNER] | V21: =IF(F21=$V$65,-1)+IF(F21=$V$66,1) -> 0
C22: Question 10 | D22: =VLOOKUP($C$6&C22,'Data Sheet Current Vulnerabilit'!$D:$E,2,FALSE) -> #N/A | F22: [SÉLECTIONNER] | V22: =IF(F22=$V$65,-1)+IF(F22=$V$66,1) -> 0
C23: Question 11 | D23: =VLOOKUP($C$6&C23,'Data Sheet Current Vulnerabilit'!$D:$E,2,FALSE) -> #N/A | F23: [SÉLECTIONNER] | V23: =IF(F23=$V$65,-1)+IF(F23=$V$66,1) -> 0
C24: Question 12 | D24: =VLOOKUP($C$6&C24,'Data Sheet Current Vulnerabilit'!$D:$E,2,FALSE) -> #N/A | F24: [SÉLECTIONNER] | V24: =IF(F24=$V$65,-1)+IF(F24=$V$66,1) -> 0
C25: Question 13 | D25: =VLOOKUP($C$6&C25,'Data Sheet Current Vulnerabilit'!$D:$E,2,FALSE) -> #N/A | F25: [SÉLECTIONNER] | V25: =IF(F25=$V$65,-1)+IF(F25=$V$66,1) -> 0
B27: Étape 4. Capacité d’adaptation
B28: A. Gestion de l’exploitation agricole | C28: Composant | F28: Réponse | Y28: Barème d’évaluation
C29: Question 14 | D29: Carte de l’exploitation | E29: =VLOOKUP($C$6&C29,'Data Sheet Current Vulnerabilit'!$D:$E,2,FALSE) -> #N/A | F29: [SÉLECTIONNER] | G29: =IF(F29=$V$65,1)+IF(F29=$V$67,0.5)+IF(F29=$V$66,0) -> 0 | U29: =G29 -> 0 | V29: =G29 -> 0 | Y29: 14 | Z29: 12 | AA29: 1 | AB29: Vulnérabilité pratiquement nulle, excellente capacité d’adaptation
C30: Question 15 | D30: Évaluation de la vulnérabilité | E30: =VLOOKUP($C$6&C30,'Data Sheet Current Vulnerabilit'!$D:$E,2,FALSE) -> #N/A | F30: [SÉLECTIONNER] | G30: =IF(F30=$V$65,1)+IF(F30=$V$67,0.5)+IF(F30=$V$66,0) -> 0 | U30: =G30 -> 0 | V30: =G30 -> 0 | Y30: 12 | Z30: 8 | AA30: 2 | AB30: Très faible vulnérabilité, capacité d’adaptation élevée
C31: Question 16 | D31: Intégration de la vulnérabilité dans les pratiques | E31: =VLOOKUP($C$6&C31,'Data Sheet Current Vulnerabilit'!$D:$E,2,FALSE) -> #N/A | F31: [SÉLECTIONNER] | G31: =IF(F31=$V$65,1)+IF(F31=$V$67,0.5)+IF(F31=$V$66,0) -> 0 | U31: =G31 -> 0 | V31: =G31 -> 0 | Y31: 8 | Z31: 4 | AA31: 3 | AB31: Faible vulnérabilité et capacité d’adaptation modérée
C32: Question 17 | D32: Plan de gestion | E32: =VLOOKUP($C$6&C32,'Data Sheet Current Vulnerabilit'!$D:$E,2,FALSE) -> #N/A | F32: [SÉLECTIONNER] | G32: =IF(F32=$V$65,1)+IF(F32=$V$67,0.5)+IF(F32=$V$66,0) -> 0 | U32: =G32 -> 0 | V32: =G32 -> 0 | Y32: 4 | Z32: 0 | AA32: 4 | AB32: Vulnérabilité et capacité d’adaptation modérées
C33: Question 18 | D33: Diversification des revenus | E33: =VLOOKUP($C$6&C33,'Data Sheet Current Vulnerabilit'!$D:$E,2,FALSE) -> #N/A | F33: [SÉLECTIONNER] | G33: =IF(F33=$V$65,1)+IF(F33=$V$67,0.5)+IF(F33=$V$66,0) -> 0 | U33: =G33 -> 0 | V33: =G33 -> 0 | Y33: 0 | Z33: -4 | AA33: 5 | AB33: Vulnérabilité modérée et faible capacité d’adaptation
C34: Question 19 | D34: Gestion des enregistrements | E34: =VLOOKUP($C$6&C34,'Data Sheet Current Vulnerabilit'!$D:$E,2,FALSE) -> #N/A | F34: [SÉLECTIONNER] | G34: =IF(F34=$V$65,1)+IF(F34=$V$67,0.5)+IF(F34=$V$66,0) -> 0 | U34: =G34 -> 0 | V34: =G34 -> 0 | Y34: -4 | Z34: -8 | AA34: 6 | AB34: Vulnérabilité élevée et très faible capacité d’adaptation
Y35: -8 | Z35: -12 | AA35: 7 | AB35: Vulnérabilité supérieure et capacité d’adaptation critique
B36: B. Gestion de l’eau | C36: Composant | F36: Réponse | Y36: -12 | Z36: -14 | AA36: 8 | AB36: Vulnérabilité extrême et capacité d’adaptation particulièrement faible
C37: Question 20 | D37: Infrastructure de captage de l’eau | E37: =VLOOKUP($C$6&C37,'Data Sheet Current Vulnerabilit'!$D:$E,2,FALSE) -> #N/A | F37: [SÉLECTIONNER] | G37: =IF(F37=$V$65,1)+IF(F37=$V$67,0.5)+IF(F37=$V$66,0) -> 0 | U37: =G37 -> 0
C38: Question 21 | D38: Système d’irrigation | E38: =VLOOKUP($C$6&C38,'Data Sheet Current Vulnerabilit'!$D:$E,2,FALSE) -> #N/A | F38: [SÉLECTIONNER] | G38: =IF(F38=$V$65,1)+IF(F38=$V$67,0.5)+IF(F38=$V$66,0) -> 0 | U38: =G38 -> 0
C39: Question 22 | D39: Entretien des réseaux d’irrigation | E39: =VLOOKUP($C$6&C39,'Data Sheet Current Vulnerabilit'!$D:$E,2,FALSE) -> #N/A | F39: [SÉLECTIONNER] | G39: =IF(F39=$V$65,1)+IF(F39=$V$67,0.5)+IF(F39=$V$66,0) -> 0 | U39: =G39 -> 0
C40: Question 23 | D40: Optimisation de l’eau d’irrigation | E40: =VLOOKUP($C$6&C40,'Data Sheet Current Vulnerabilit'!$D:$E,2,FALSE) -> #N/A | F40: [SÉLECTIONNER] | G40: =IF(F40=$V$65,1)+IF(F40=$V$67,0.5)+IF(F40=$V$66,0) -> 0 | U40: =G40 -> 0
C41: Question 24a | D41: Écosystèmes aquatiques | E41: =VLOOKUP($C$6&C41,'Data Sheet Current Vulnerabilit'!$D:$E,2,FALSE) -> #N/A | F41: [SÉLECTIONNER] | G41: =IF(F41=$V$65,1)+IF(F41=$V$67,0.5)+IF(F41=$V$66,0) -> 0 | U41: =G41 -> 0
C42: Question 24b | D42: Protection des écosystèmes aquatiques | E42: =VLOOKUP($C$6&C42,'Data Sheet Current Vulnerabilit'!$D:$E,2,FALSE) -> #N/A | F42: [SÉLECTIONNER] | G42: =IF(F42=$V$65,1)+IF(F42=$V$67,0.5)+IF(F42=$V$66,0) -> 0 | U42: =G42 -> 0
B44: C. Conservation des sols | C44: Composant | F44: Réponse
C45: Question 25 | D45: Incorporation d’engrais biologiques | E45: =VLOOKUP($C$6&C45,'Data Sheet Current Vulnerabilit'!$D:$E,2,FALSE) -> #N/A | F45: [SÉLECTIONNER] | G45: =IF(F45=$V$65,1)+IF(F45=$V$67,0.5)+IF(F45=$V$66,0) -> 0 | U45: =G45 -> 0
C46: Question 26 | D46: Cultures de couverture | E46: =VLOOKUP($C$6&C46,'Data Sheet Current Vulnerabilit'!$D:$E,2,FALSE) -> #N/A | F46: [SÉLECTIONNER] | G46: =IF(F46=$V$65,1)+IF(F46=$V$67,0.5)+IF(F46=$V$66,0) -> 0 | U46: =G46 -> 0
C47: Question 27 | D47: Mulching | E47: =VLOOKUP($C$6&C47,'Data Sheet Current Vulnerabilit'!$D:$E,2,FALSE) -> #N/A | F47: [SÉLECTIONNER] | G47: =IF(F47=$V$65,1)+IF(F47=$V$67,0.5)+IF(F47=$V$66,0) -> 0 | U47: =G47 -> 0
C48: Question 28 | D48: Stratégies de conservation des sols | E48: =VLOOKUP($C$6&C48,'Data Sheet Current Vulnerabilit'!$D:$E,2,FALSE) -> #N/A | F48: [SÉLECTIONNER] | G48: =IF(F48=$V$65,1)+IF(F48=$V$67,0.5)+IF(F48=$V$66,0) -> 0 | U48: =G48 -> 0
...

Sheet 3. RÉSULTATS
B1: Page de résultats de l'évaluation des risques du changement climatique.
B2: Pour imprimer vos résultats, il est recommandé de procéder par Résultat. Veillez à sélectionner la case correspondant au résultat recherché, puis sélectionner le fichier « File » et cliquez sur « Print » pour imprimer. Dans la rubrique de réglages « Settings », dans le premier menu déroulant, sélectionnez « Print Selection », puis sélectionnez la commande d’ajustement de la page d’impression à une feuille « Fit Sheet on One page » dans le menu déroulant du bas. Pour les Résultats 2, sélectionner l’orientation en paysage « Landscape Orientation ».
B3: RÉSULTATS 1. | H3: RÉSULTATS 2. | AK3: RÉSULTATS 3.
B5: 3.1 NIVEAU DE RISQUE CLIMATIQUE | H5: CAPACITÉ D’ADAPTATION (générale) | N5: CAPACITÉ D’ADAPTATION (générale) | AK5: Actions d’atténuation générale
B6: NIVEAUX | E6: Niveau | F6: Risque climatique | H6: COEFFICIENT DE RÉSILIENCE | N6: A. Gestion de l’exploitation agricole | Z6: D. Gestion de la végétation naturelle | AK6: Ces mesures d’amélioration ont pour but de renforcer la résilience de votre exploitation. Identifiez les actions les mieux adaptées à votre situation sur la base de l’exploitation, de vos moyens et du contexte.
B7: EXPOSITION | C7: =SUM('2. SAISIE DES DONNÉES'!V10:V16) -> 0 | F7: Risque climatique pratiquement nul (score 14 à 12) | H7: Le coefficient de résilience (score maxi : 1) est le score moyen de vos pratiques actuelles dans les catégories Exploitation, Eau, Sol, Végétation naturelle et Gestion des cultures. Plus le score est élevé, meilleure est la résilience de l’exploitation. Consultez votre score par catégorie afin d’identifier les domaines susceptibles d’améliorations. Votre capacité d’adaptation détermine l’amélioration potentielle que vous pouvez réaliser en fonction du contexte. | AK7: Atténuation 1 | AL7: =VLOOKUP('2. SAISIE DES DONNÉES'!$C$6&'3. RÉSULTATS'!AK7,Mitigations!$I$28:$J$231,2,FALSE) -> #N/A
B8: IMPACTS | C8: =SUM('2. SAISIE DES DONNÉES'!V19:V25) -> 0 | F8: Risque climatique très faible (score 12 à 8) | H8: Coefficient de résilience | I8: =AVERAGEIF('2. SAISIE DES DONNÉES'!F29:F61,"<>"&'2. SAISIE DES DONNÉES'!$V$68,'2. SAISIE DES DONNÉES'!G29:G61) -> 0 | AK8: Atténuation 2 | AL8: =VLOOKUP('2. SAISIE DES DONNÉES'!$C$6&'3. RÉSULTATS'!AK8,Mitigations!$I$28:$J$231,2,FALSE) -> #N/A
B9: RISQUE CLIMATIQUE ACTUEL (Changements de couleur en fonction du score, ne pas modifier) | C9: =SUM(C7:C8) -> 0 | D9: Comparez la couleur au tableau (ou utilisez le score) --> | F9: Risque climatique faible (score 8 à 4) | H9: Gestion de l’exploitation agricole | I9: =AVERAGEIF('2. SAISIE DES DONNÉES'!F29:F34,"<>"&'2. SAISIE DES DONNÉES'!$V$68,'2. SAISIE DES DONNÉES'!G29:G34) -> 0 | AK9: Atténuation 3 | AL9: =VLOOKUP('2. SAISIE DES DONNÉES'!$C$6&'3. RÉSULTATS'!AK9,Mitigations!$I$28:$J$231,2,FALSE) -> #N/A
B10: Le score de risque climatique est indiqué par la couleur correspondante sur la base de vos réponses aux questions des catégories Exposition et impact. Le score élevé est 14 et le plus faible est –14. Nous insistons sur le fait que ce score est indicatif et qu’il a pour objet de mieux montrer l’importance du changement climatique pour vous, mais pour indiquer que l’essentiel n’est pas uniquement le nombre mais votre prise de conscience des menaces que le changement climatique fait peser sur votre système d’exploitation agricole. | F10: Risque climatique modéré (score 4 à 0) | H10: Gestion de l’eau | I10: =AVERAGEIF('2. SAISIE DES DONNÉES'!F37:F42,"<>"&'2. SAISIE DES DONNÉES'!$V$68,'2. SAISIE DES DONNÉES'!G37:G42) -> 0 | AK10: Atténuation 4 | AL10: =VLOOKUP('2. SAISIE DES DONNÉES'!$C$6&'3. RÉSULTATS'!AK10,Mitigations!$I$28:$J$231,2,FALSE) -> #N/A
F11: Risque climatique très modéré (score 0 à –4) | H11: Gestion des sols | I11: =AVERAGEIF('2. SAISIE DES DONNÉES'!F45:F49,"<>"&'2. SAISIE DES DONNÉES'!$V$68,'2. SAISIE DES DONNÉES'!G45:G49) -> 0 | AK11: Atténuation 5 | AL11: =VLOOKUP('2. SAISIE DES DONNÉES'!$C$6&'3. RÉSULTATS'!AK11,Mitigations!$I$28:$J$231,2,FALSE) -> #N/A
F12: Risque climatique élevé (score –4 à –8) | H12: Gestion de la végétation naturelle | I12: =AVERAGEIF('2. SAISIE DES DONNÉES'!F52:F55,"<>"&'2. SAISIE DES DONNÉES'!$V$68,'2. SAISIE DES DONNÉES'!G52:G55) -> 0 | AK12: Atténuation 6 | AL12: =VLOOKUP('2. SAISIE DES DONNÉES'!$C$6&'3. RÉSULTATS'!AK12,Mitigations!$I$28:$J$231,2,FALSE) -> #N/A
F13: Risque climatique très élevé (score –8 à –12) | H13: Gestion des cultures | I13: =AVERAGEIF('2. SAISIE DES DONNÉES'!F58:F61,"<>"&'2. SAISIE DES DONNÉES'!$V$68,'2. SAISIE DES DONNÉES'!G58:G61) -> 0 | AK13: Atténuation 7 | AL13: =VLOOKUP('2. SAISIE DES DONNÉES'!$C$6&'3. RÉSULTATS'!AK13,Mitigations!$I$28:$J$231,2,FALSE) -> #N/A
F14: Risque climatique critique/très élevé (score –12 à –14) | AK14: Atténuation 8 | AL14: =VLOOKUP('2. SAISIE DES DONNÉES'!$C$6&'3. RÉSULTATS'!AK14,Mitigations!$I$28:$J$231,2,FALSE) -> #N/A
N15: B. Gestion de l’eau | Z15: E. Gestion des cultures | AK15: Atténuation 9 | AL15: =VLOOKUP('2. SAISIE DES DONNÉES'!$C$6&'3. RÉSULTATS'!AK15,Mitigations!$I$28:$J$231,2,FALSE) -> #N/A
AK16: Atténuation 10 | AL16: =VLOOKUP('2. SAISIE DES DONNÉES'!$C$6&'3. RÉSULTATS'!AK16,Mitigations!$I$28:$J$231,2,FALSE) -> #N/A
AK17: Atténuation 11 | AL17: =VLOOKUP('2. SAISIE DES DONNÉES'!$C$6&'3. RÉSULTATS'!AK17,Mitigations!$I$28:$J$231,2,FALSE) -> #N/A
AK18: Atténuation 12 | AL18: =VLOOKUP('2. SAISIE DES DONNÉES'!$C$6&'3. RÉSULTATS'!AK18,Mitigations!$I$28:$J$231,2,FALSE) -> #N/A
AL20: =VLOOKUP('2. SAISIE DES DONNÉES'!$C$6&AK20,Mitigations!$I$28:$J$157,2,FALSE) -> #N/A
N30: C. Gestion des sols

Sheet Mitigations
A1: Niveau | B1: Produit agricole | C1: Question | D1: Concate1 | E1: Question (Consultation 1) | F1: Réponse | G1: Concate2 | H1: Réponse (Consultation 2) | I1: Concat3 | J1: Action d’atténuation (Consultation 3)
A2: Exposition | B2: cacao | C2: Question 1 | D2: =CONCATENATE(B2,C2) -> cacaoQuestion 1 | E2: La température a-t-elle changé au cours des 10 dernières années ? | F2: oui | G2: =CONCATENATE(E2,F2) -> La température a-t-elle changé au cours des 10 dernières années ? oui | H2: =IF(F2='2. SAISIE DES DONNÉES'!$V$65,-1)+IF(F2='2. SAISIE DES DONNÉES'!$V$66,1) -> -1 | I2: =CONCATENATE(B2,F2) -> cacaooui
A3: Exposition | B3: cacao | C3: Question 1 | D3: =CONCATENATE(B3,C3) -> cacaoQuestion 1 | E3: La température a-t-elle changé au cours des 10 dernières années ? | F3: non | G3: =CONCATENATE(E3,F3) -> La température a-t-elle changé au cours des 10 dernières années ? non | H3: =IF(F3='2. SAISIE DES DONNÉES'!$V$65,-1)+IF(F3='2. SAISIE DES DONNÉES'!$V$66,1) -> 1 | I3: =CONCATENATE(B3,F3) -> cacaonon
A4: Exposition | B4: café | C4: Question 1 | D4: =CONCATENATE(B4,C4) -> caféQuestion 1 | E4: La température a-t-elle changé au cours des 10 dernières années ? | F4: oui | G4: =CONCATENATE(E4,F4) -> La température a-t-elle changé au cours des 10 dernières années ? oui | H4: =IF(F4='2. SAISIE DES DONNÉES'!$V$65,-1)+IF(F4='2. SAISIE DES DONNÉES'!$V$66,1) -> -1 | I4: =CONCATENATE(B4,F4) -> caféoui
A5: Exposition | B5: café | C5: Question 1 | D5: =CONCATENATE(B5,C5) -> caféQuestion 1 | E5: La température a-t-elle changé au cours des 10 dernières années ? | F5: non | G5: =CONCATENATE(E5,F5) -> La température a-t-elle changé au cours des 10 dernières années ? non | H5: =IF(F5='2. SAISIE DES DONNÉES'!$V$65,-1)+IF(F5='2. SAISIE DES DONNÉES'!$V$66,1) -> 1 | I5: =CONCATENATE(B5,F5) -> cafénon
A6: Exposition | B6: thé | C6: Question 1 | D6: =CONCATENATE(B6,C6) -> théQuestion 1 | E6: La température a-t-elle changé au cours des 10 dernières années ? | F6: oui | G6: =CONCATENATE(E6,F6) -> La température a-t-elle changé au cours des 10 dernières années ? oui | H6: =IF(F6='2. SAISIE DES DONNÉES'!$V$65,-1)+IF(F6='2. SAISIE DES DONNÉES'!$V$66,1) -> -1 | I6: =CONCATENATE(B6,F6) -> théoui
A7: Exposition | B7: thé | C7: Question 1 | D7: =CONCATENATE(B7,C7) -> théQuestion 1 | E7: La température a-t-elle changé au cours des 10 dernières années ? | F7: non | G7: =CONCATENATE(E7,F7) -> La température a-t-elle changé au cours des 10 dernières années ? non | H7: =IF(F7='2. SAISIE DES DONNÉES'!$V$65,-1)+IF(F7='2. SAISIE DES DONNÉES'!$V$66,1) -> 1 | I7: =CONCATENATE(B7,F7) -> thénon
A8: Exposition | B8: les bananes | C8: Question 1 | D8: =CONCATENATE(B8,C8) -> les bananesQuestion 1 | E8: La température a-t-elle changé au cours des 10 dernières années ? | F8: oui | G8: =CONCATENATE(E8,F8) -> La température a-t-elle changé au cours des 10 dernières années ? oui | H8: =IF(F8='2. SAISIE DES DONNÉES'!$V$65,-1)+IF(F8='2. SAISIE DES DONNÉES'!$V$66,1) -> -1 | I8: =CONCATENATE(B8,F8) -> les bananesoui
A9: Exposition | B9: les bananes | C9: Question 1 | D9: =CONCATENATE(B9,C9) -> les bananesQuestion 1 | E9: La température a-t-elle changé au cours des 10 dernières années ? | F9: non | G9: =CONCATENATE(E9,F9) -> La température a-t-elle changé au cours des 10 dernières années ? non | H9: =IF(F9='2. SAISIE DES DONNÉES'!$V$65,-1)+IF(F9='2. SAISIE DES DONNÉES'!$V$66,1) -> 1 | I9: =CONCATENATE(B9,F9) -> les bananesnon
A10: Impacts | B10: cacao | C10: Question 10 | D10: =CONCATENATE(B10,C10) -> cacaoQuestion 10 | E10: Constatez-vous une augmentation de la chute des fleurs et des fruits ? | F10: oui | G10: =CONCATENATE(E10,F10) -> Constatez-vous une augmentation de la chute des fleurs et des fruits ? oui | H10: =IF(F10='2. SAISIE DES DONNÉES'!$V$65,-1)+IF(F10='2. SAISIE DES DONNÉES'!$V$66,1) -> -1 | I10: =CONCATENATE(B10,F10) -> cacaooui
A11: Impacts | B11: cacao | C11: Question 10 | D11: =CONCATENATE(B11,C11) -> cacaoQuestion 10 | E11: Constatez-vous une augmentation de la chute des fleurs et des fruits ? | F11: non | G11: =CONCATENATE(E11,F11) -> Constatez-vous une augmentation de la chute des fleurs et des fruits ? non | H11: =IF(F11='2. SAISIE DES DONNÉES'!$V$65,-1)+IF(F11='2. SAISIE DES DONNÉES'!$V$66,1) -> 1 | I11: =CONCATENATE(B11,F11) -> cacaonon
A12: Impacts | B12: café | C12: Question 10 | D12: =CONCATENATE(B12,C12) -> caféQuestion 10 | E12: Constatez-vous une augmentation de la chute des fleurs et des fruits ? | F12: oui | G12: =CONCATENATE(E12,F12) -> Constatez-vous une augmentation de la chute des fleurs et des fruits ? oui | H12: =IF(F12='2. SAISIE DES DONNÉES'!$V$65,-1)+IF(F12='2. SAISIE DES DONNÉES'!$V$66,1) -> -1 | I12: =CONCATENATE(B12,F12) -> caféoui
A13: Impacts | B13: café | C13: Question 10 | D13: =CONCATENATE(B13,C13) -> caféQuestion 10 | E13: Constatez-vous une augmentation de la chute des fleurs et des fruits ? | F13: non | G13: =CONCATENATE(E13,F13) -> Constatez-vous une augmentation de la chute des fleurs et des fruits ? non | H13: =IF(F13='2. SAISIE DES DONNÉES'!$V$65,-1)+IF(F13='2. SAISIE DES DONNÉES'!$V$66,1) -> 1 | I13: =CONCATENATE(B13,F13) -> cafénon
... A27: Impacts | B27: cacao | C27: Question 12 | D27: =CONCATENATE(B27,C27) -> cacaoQuestion 12 | E27: Les dégâts des ravageurs et des maladies sur le système de production ont-ils augmenté au cours des 5 à 10 dernières années ? | F27: non | G27: =CONCATENATE(E27,F27) -> Les dégâts des ravageurs et des maladies sur le système de production ont-ils augmenté au cours des 5 à 10 dernières années ? non | H27: =IF(F27='2. SAISIE DES DONNÉES'!$V$65,-1)+IF(F27='2. SAISIE DES DONNÉES'!$V$66,1) -> 1 | I27: =CONCATENATE(B27,F27) -> cacaonon
A28: Impacts | B28: café | C28: Question 12 | D28: =CONCATENATE(B28,C28) -> caféQuestion 12 | E28: Les dégâts des ravageurs et des maladies sur le système de production ont-ils augmenté au cours des 5 à 10 dernières années ? | F28: oui | G28: =CONCATENATE(E28,F28) -> Les dégâts des ravageurs et des maladies sur le système de production ont-ils augmenté au cours des 5 à 10 dernières années ? oui | H28: =IF(F28='2. SAISIE DES DONNÉES'!$V$65,-1)+IF(F28='2. SAISIE DES DONNÉES'!$V$66,1) -> -1 | I28: =CONCATENATE(B28,F28) -> caféoui | J28: Sur la base de l’évaluation des sols, identifier les zones exposées aux risques d’érosion et mettre en place des pratiques de conservation des sols telles que terrasses, terrasses individuelles, conservation des sols, etc.
A29: Impacts | B29: café | C29: Question 12 | D29: =CONCATENATE(B29,C29) -> caféQuestion 12 | E29: Les dégâts des ravageurs et des maladies sur le système de production ont-ils augmenté au cours des 5 à 10 dernières années ? | F29: non | G29: =CONCATENATE(E29,F29) -> Les dégâts des ravageurs et des maladies sur le système de production ont-ils augmenté au cours des 5 à 10 dernières années ? non | H29: =IF(F29='2. SAISIE DES DONNÉES'!$V$65,-1)+IF(F29='2. SAISIE DES DONNÉES'!$V$66,1) -> 1 | I29: =CONCATENATE(B29,F29) -> cafénon | J29: Le sol de la zone de production n’est pas laissé à nu, il est protégé par des mesures telles que des cultures de couverture et du paillis afin de limiter l’érosion et la perte de nutriments au profit de l’augmentation des nutriments et de la ressource en eau
A30: Impacts | B30: thé | C30: Question 12 | D30: =CONCATENATE(B30,C30) -> théQuestion 12 | E30: Les dégâts des ravageurs et des maladies sur le système de production ont-ils augmenté au cours des 5 à 10 dernières années ? | F30: oui | G30: =CONCATENATE(E30,F30) -> Les dégâts des ravageurs et des maladies sur le système de production ont-ils augmenté au cours des 5 à 10 dernières années ? oui | H30: =IF(F30='2. SAISIE DES DONNÉES'!$V$65,-1)+IF(F30='2. SAISIE DES DONNÉES'!$V$66,1) -> -1 | I30: =CONCATENATE(B30,F30) -> théoui | J30: Mettre en œuvre des mesures de diversification des systèmes de production tels qu’une augmentation du nombre d’arbres fruitier, du bois d’œuvre et des cultures alimentaires
A31: Impacts | B31: thé | C31: Question 12 | D31: =CONCATENATE(B31,C31) -> théQuestion 12 | E31: Les dégâts des ravageurs et des maladies sur le système de production ont-ils augmenté au cours des 5 à 10 dernières années ? | F31: non | G31: =CONCATENATE(E31,F31) -> Les dégâts des ravageurs et des maladies sur le système de production ont-ils augmenté au cours des 5 à 10 dernières années ? non | H31: =IF(F31='2. SAISIE DES DONNÉES'!$V$65,-1)+IF(F31='2. SAISIE DES DONNÉES'!$V$66,1) -> 1 | I31: =CONCATENATE(B31,F31) -> thénon | J31: Si les systèmes de production sont exposés en plein soleil, essayer de renforcer l’ombrage jusqu’au seuil optimal de couverture. En cas d’ombrage excessif, mettre en œuvre des activités de gestion de l’ombre permettant d’atteindre le seuil optimal
A32: Impacts | B32: les bananes | C32: Question 12 | D32: =CONCATENATE(B32,C32) -> les bananesQuestion 12 | E32: Les dégâts des ravageurs et des maladies sur le système de production ont-ils augmenté au cours des 5 à 10 dernières années ? | F32: oui | G32: =CONCATENATE(E32,F32) -> Les dégâts des ravageurs et des maladies sur le système de production ont-ils augmenté au cours des 5 à 10 dernières années ? oui | H32: =IF(F32='2. SAISIE DES DONNÉES'!$V$65,-1)+IF(F32='2. SAISIE DES DONNÉES'!$V$66,1) -> -1 | I32: =CONCATENATE(B32,F32) -> les bananesoui | J32: Mettre en œuvre une taille ou un élagage progressif de rajeunissement ou la plantation progressive de nouvelles plantes. Sélectionner les nouveaux plants en fonction des conditions climatiques futures.
A33: Impacts | B33: les bananes | C33: Question 12 | D33: =CONCATENATE(B33,C33) -> les bananesQuestion 12 | E33: Les dégâts des ravageurs et des maladies sur le système de production ont-ils augmenté au cours des 5 à 10 dernières années ? | F33: non | G33: =CONCATENATE(E33,F33) -> Les dégâts des ravageurs et des maladies sur le système de production ont-ils augmenté au cours des 5 à 10 dernières années ? non | H33: =IF(F33='2. SAISIE DES DONNÉES'!$V$65,-1)+IF(F33='2. SAISIE DES DONNÉES'!$V$66,1) -> 1 | I33: =CONCATENATE(B33,F33) -> les bananesnon | J33: Améliorer la surveillance des ravageurs et des maladies afin d’en évaluer les impacts sur les cacaoyers
A34: Impacts | B34: cacao | C34: Question 13 | D34: =CONCATENATE(B34,C34) -> cacaoQuestion 13 | E34: La productivité a-t-elle diminué au cours des dernières années (5 à 10 ans) ? | F34: oui | G34: =CONCATENATE(E34,F34) -> La productivité a-t-elle diminué au cours des dernières années (5 à 10 ans) ? oui | H34: =IF(F34='2. SAISIE DES DONNÉES'!$V$65,-1)+IF(F34='2. SAISIE DES DONNÉES'!$V$66,1) -> -1 | I34: =CONCATENATE(B34,F34) -> cacaooui | J34: Maintenir les pratiques de taille et d’élagage
A35: Impacts | B35: cacao | C35: Question 13 | D35: =CONCATENATE(B35,C35) -> cacaoQuestion 13 | E35: La productivité a-t-elle diminué au cours des dernières années (5 à 10 ans) ? | F35: non | G35: =CONCATENATE(E35,F35) -> La productivité a-t-elle diminué au cours des dernières années (5 à 10 ans) ? non | H35: =IF(F35='2. SAISIE DES DONNÉES'!$V$65,-1)+IF(F35='2. SAISIE DES DONNÉES'!$V$66,1) -> 1 | I35: =CONCATENATE(B35,F35) -> cacaonon | J35: Replanter les plantes malades conformément à la stratégie de LIR
A36: Impacts | B36: café | C36: Question 13 | D36: =CONCATENATE(B36,C36) -> caféQuestion 13 | E36: La productivité a-t-elle diminué au cours des dernières années (5 à 10 ans) ? | F36: oui | G36: =CONCATENATE(E36,F36) -> La productivité a-t-elle diminué au cours des dernières années (5 à 10 ans) ? oui | H36: =IF(F36='2. SAISIE DES DONNÉES'!$V$65,-1)+IF(F36='2. SAISIE DES DONNÉES'!$V$66,1) -> -1 | I36: =CONCATENATE(B36,F36) -> caféoui | J36: Épandre en premier lieu les engrais biologiques et les sous-produits disponibles sur l’exploitation, puis compléter avec des engrais chimiques si les nutriments restent insuffisants.
A37: Impacts | B37: café | C37: Question 13 | D37: =CONCATENATE(B37,C37) -> caféQuestion 13 | E37: La productivité a-t-elle diminué au cours des dernières années (5 à 10 ans) ? | F37: non | G37: =CONCATENATE(E37,F37) -> La productivité a-t-elle diminué au cours des dernières années (5 à 10 ans) ? non | H37: =IF(F37='2. SAISIE DES DONNÉES'!$V$65,-1)+IF(F37='2. SAISIE DES DONNÉES'!$V$66,1) -> 1 | I37: =CONCATENATE(B37,F37) -> cafénon | J37: Épandre en premier lieu les engrais biologiques et les sous-produits disponibles sur l’exploitation, puis compléter avec des engrais chimiques si les nutriments restent insuffisants.
A38: Impacts | B38: thé | C38: Question 13 | D38: =CONCATENATE(B38,C38) -> théQuestion 13 | E38: La productivité a-t-elle diminué au cours des dernières années (5 à 10 ans) ? | F38: oui | G38: =CONCATENATE(E38,F38) -> La productivité a-t-elle diminué au cours des dernières années (5 à 10 ans) ? oui | H38: =IF(F38='2. SAISIE DES DONNÉES'!$V$65,-1)+IF(F38='2. SAISIE DES DONNÉES'!$V$66,1) -> -1 | I38: =CONCATENATE(B38,F38) -> théoui | J38: Les écosystèmes aquatiques sont entourés de zones ripariennes tampons dont la largeur correspond aux paramètres des exigences standards
A39: Impacts | B39: thé | C39: Question 13 | D39: =CONCATENATE(B39,C39) -> théQuestion 13 | E39: La productivité a-t-elle diminué au cours des dernières années (5 à 10 ans) ? | F39: non | G39: =CONCATENATE(E39,F39) -> La productivité a-t-elle diminué au cours des dernières années (5 à 10 ans) ? non | H39: =IF(F39='2. SAISIE DES DONNÉES'!$V$65,-1)+IF(F39='2. SAISIE DES DONNÉES'!$V$66,1) -> 1 | I39: =CONCATENATE(B39,F39) -> thénon | J39: Augmenter la couverture de végétation naturelle sur l’exploitation pour renforcer l’apport et la résilience de la biodiversité et de l’écosystème.
A40: Impacts | B40: les bananes | C40: Question 13 | D40: =CONCATENATE(B40,C40) -> les bananesQuestion 13 | E40: La productivité a-t-elle diminué au cours des dernières années (5 à 10 ans) ? | F40: oui | G40: =CONCATENATE(E40,F40) -> La productivité a-t-elle diminué au cours des dernières années (5 à 10 ans) ? oui | H40: =IF(F40='2. SAISIE DES DONNÉES'!$V$65,-1)+IF(F40='2. SAISIE DES DONNÉES'!$V$66,1) -> -1 | I40: =CONCATENATE(B40,F40) -> les bananesoui | J40: Prendre en compte les impacts actuels et futurs du changement climatique lors du développement des plans de gestion des cultures et de l’exploitation
A41: Impacts | B41: les bananes | C41: Question 13 | D41: =CONCATENATE(B41,C41) -> les bananesQuestion 13 | E41: La productivité a-t-elle diminué au cours des dernières années (5 à 10 ans) ? | F41: non | G41: =CONCATENATE(E41,F41) -> La productivité a-t-elle diminué au cours des dernières années (5 à 10 ans) ? non | H41: =IF(F41='2. SAISIE DES DONNÉES'!$V$65,-1)+IF(F41='2. SAISIE DES DONNÉES'!$V$66,1) -> 1 | I41: =CONCATENATE(B41,F41) -> les bananesnon
A42: Capacité d’adaptation | B42: cacao | C42: Question 14 | D42: =CONCATENATE(B42,C42) -> cacaoQuestion 14 | E42: Existe-t-il une carte (éventuellement un croquis) de l’exploitation qui identifie les zones de production, les aires de conservation, les écosystèmes aquatiques et les zones potentiellement vulnérables (zones inondables, exposées à l’érosion, etc.) ? | F42: Atténuation 1 | G42: =CONCATENATE(E42,F42) -> Existe-t-il une carte (éventuellement un croquis) de l’exploitation qui identifie les zones de production, les aires de conservation, les écosystèmes aquatiques et les zones potentiellement vulnérables (zones inondables, exposées à l’érosion, etc.) ?Atténuation 1 | H42: =IF(F42='2. SAISIE DES DONNÉES'!$V$65,-1)+IF(F42='2. SAISIE DES DONNÉES'!$V$66,1) -> 0 | I42: =CONCATENATE(B42,F42) -> cacaoAtténuation 1 | J42: Sur la base de l’évaluation des sols, identifier les zones exposées aux risques d’érosion et mettre en œuvre des pratiques de conservation des sols telles que terrasses, terrasses individuelles, paillage, etc.)
A43: Capacité d’adaptation | B43: café | C43: Question 14 | D43: =CONCATENATE(B43,C43) -> caféQuestion 14 | E43: Existe-t-il une carte (éventuellement un croquis) de l’exploitation qui identifie les zones de production, les aires de conservation, les écosystèmes aquatiques et les zones potentiellement vulnérables (zones inondables, exposées à l’érosion, etc.) ? | F43: Atténuation 1 | G43: =CONCATENATE(E43,F43) -> Existe-t-il une carte (éventuellement un croquis) de l’exploitation qui identifie les zones de production, les aires de conservation, les écosystèmes aquatiques et les zones potentiellement vulnérables (zones inondables, exposées à l’érosion, etc.) ?Atténuation 1 | H43: =IF(F43='2. SAISIE DES DONNÉES'!$V$65,-1)+IF(F43='2. SAISIE DES DONNÉES'!$V$66,1) -> 0 | I43: =CONCATENATE(B43,F43) -> caféAtténuation 1 | J43: Sur la base de l’évaluation des sols, identifier les zones exposées aux risques d’érosion et mettre en place des pratiques de conservation des sols telles que terrasses, terrasses individuelles, couverture des sols, etc.)
A44: Capacité d’adaptation | B44: thé | C44: Question 14 | D44: =CONCATENATE(B44,C44) -> théQuestion 14 | E44: Existe-t-il une carte (éventuellement un croquis) de l’exploitation qui identifie les zones de production, les aires de conservation, les écosystèmes aquatiques et les zones potentiellement vulnérables (zones inondables, exposées à l’érosion, etc.) ? | F44: Atténuation 1 | G44: =CONCATENATE(E44,F44) -> Existe-t-il une carte (éventuellement un croquis) de l’exploitation qui identifie les zones de production, les aires de conservation, les écosystèmes aquatiques et les zones potentiellement vulnérables (zones inondables, exposées à l’érosion, etc.) ?Atténuation 1 | H44: =IF(F44='2. SAISIE DES DONNÉES'!$V$65,-1)+IF(F44='2. SAISIE DES DONNÉES'!$V$66,1) -> 0 | I44: =CONCATENATE(B44,F44) -> théAtténuation 1 | J44: Sur la base de l’évaluation des sols, identifier les zones exposées aux risques d’érosion et mettre en place des pratiques de conservation des sols telles que terrasses, terrasses individuelles, couverture des sols, etc.)
A45: Capacité d’adaptation | B45: les bananes | C45: Question 14 | D45: =CONCATENATE(B45,C45) -> les bananesQuestion 14 | E45: Existe-t-il une carte (éventuellement un croquis) de l’exploitation qui identifie les zones de production, les aires de conservation, les écosystèmes aquatiques et les zones potentiellement vulnérables (zones inondables, exposées à l’érosion, etc.) ? | F45: Atténuation 1 | G45: =CONCATENATE(E45,F45) -> Existe-t-il une carte (éventuellement un croquis) de l’exploitation qui identifie les zones de production, les aires de conservation, les écosystèmes aquatiques et les zones potentiellement vulnérables (zones inondables, exposées à l’érosion, etc.) ?Atténuation 1 | H45: =IF(F45='2. SAISIE DES DONNÉES'!$V$65,-1)+IF(F45='2. SAISIE DES DONNÉES'!$V$66,1) -> 0 | I45: =CONCATENATE(B45,F45) -> les bananesAtténuation 1 | J45: Entretenir les canaux de drainage pour prévenir l’érosion et protéger l’eau.
A46: Capacité d’adaptation | B46: cacao | C46: Question 15 | D46: =CONCATENATE(B46,C46) -> cacaoQuestion 15 | E46: Les risques climatiques futurs ont-ils été identifiés sur la base des niveaux de vulnérabilité ? | F46: Atténuation 2 | G46: =CONCATENATE(E46,F46) -> Les risques climatiques futurs ont-ils été identifiés sur la base des niveaux de vulnérabilité ?Atténuation 2 | H46: =IF(F46='2. SAISIE DES DONNÉES'!$V$65,-1)+IF(F46='2. SAISIE DES DONNÉES'!$V$66,1) -> 0 | I46: =CONCATENATE(B46,F46) -> cacaoAtténuation 2 | J46: Le sol de la zone de production n’est pas laissé à nu, il est protégé par des mesures telles que des cultures de couverture et du paillis afin de limiter l’érosion et la perte de nutriments au profit de l’augmentation des nutriments et de la ressource en eau
A47: Capacité d’adaptation | B47: café | C47: Question 15 | D47: =CONCATENATE(B47,C47) -> caféQuestion 15 | E47: Les risques climatiques futurs ont-ils été identifiés sur la base des niveaux de vulnérabilité ? | F47: Atténuation 2 | G47: =CONCATENATE(E47,F47) -> Les risques climatiques futurs ont-ils été identifiés sur la base des niveaux de vulnérabilité ?Atténuation 2 | H47: =IF(F47='2. SAISIE DES DONNÉES'!$V$65,-1)+IF(F47='2. SAISIE DES DONNÉES'!$V$66,1) -> 0 | I47: =CONCATENATE(B47,F47) -> caféAtténuation 2 | J47: Le sol de la zone de production n’est pas laissé à nu, il est protégé par des mesures telles que des cultures de couverture et du paillis afin de limiter l’érosion et la perte de nutriments au profit de l’augmentation des nutriments et de la ressource en eau
A48: Capacité d’adaptation | B48: thé | C48: Question 15 | D48: =CONCATENATE(B48,C48) -> théQuestion 15 | E48: Les risques climatiques futurs ont-ils été identifiés sur la base des niveaux de vulnérabilité ? | F48: Atténuation 2 | G48: =CONCATENATE(E48,F48) -> Les risques climatiques futurs ont-ils été identifiés sur la base des niveaux de vulnérabilité ?Atténuation 2 | H48: =IF(F48='2. SAISIE DES DONNÉES'!$V$65,-1)+IF(F48='2. SAISIE DES DONNÉES'!$V$66,1) -> 0 | I48: =CONCATENATE(B48,F48) -> théAtténuation 2 | J48: Le sol de la zone de production n’est pas laissé à nu, il est protégé par des mesures telles que des cultures de couverture et du paillis afin de limiter l’érosion et la perte de nutriments au profit de l’augmentation des nutriments et de la ressource en eau
A49: Capacité d’adaptation | B49: les bananes | C49: Question 15 | D49: =CONCATENATE(B49,C49) -> les bananesQuestion 15 | E49: Les risques climatiques futurs ont-ils été identifiés sur la base des niveaux de vulnérabilité ? | F49: Atténuation 2 | G49: =CONCATENATE(E49,F49) -> Les risques climatiques futurs ont-ils été identifiés sur la base des niveaux de vulnérabilité ?Atténuation 2 | H49: =IF(F49='2. SAISIE DES DONNÉES'!$V$65,-1)+IF(F49='2. SAISIE DES DONNÉES'!$V$66,1) -> 0 | I49: =CONCATENATE(B49,F49) -> les bananesAtténuation 2 | J49: Le sol de la zone de production n’est pas laissé à nu, il est protégé par des mesures telles que des cultures de couverture et du paillis afin de limiter l’érosion et la perte de nutriments au profit de l’augmentation des nutriments et de la ressource en eau.
A50: Capacité d’adaptation | B50: cacao | C50: Question 16 | D50: =CONCATENATE(B50,C50) -> cacaoQuestion 16 | E50: Les pratiques agricoles ont-elles été associées en vue de compenser les vulnérabilités climatiques identifiées ? | F50: Atténuation 3 | G50: =CONCATENATE(E50,F50) -> Les pratiques agricoles ont-elles été associées en vue de compenser les vulnérabilités climatiques identifiées ?Atténuation 3 | H50: =IF(F50='2. SAISIE DES DONNÉES'!$V$65,-1)+IF(F50='2. SAISIE DES DONNÉES'!$V$66,1) -> 0 | I50: =CONCATENATE(B50,F50) -> cacaoAtténuation 3 | J50: Mettre en œuvre des mesures de diversification des systèmes de production tels qu’une augmentation du nombre d’arbres fruitier, du bois d’œuvre et des cultures alimentaires
A51: Capacité d’adaptation | B51: café | C51: Question 16 | D51: =CONCATENATE(B51,C51) -> caféQuestion 16 | E51: Les pratiques agricoles ont-elles été associées en vue de compenser les vulnérabilités climatiques identifiées ? | F51: Atténuation 3 | G51: =CONCATENATE(E51,F51) -> Les pratiques agricoles ont-elles été associées en vue de compenser les vulnérabilités climatiques identifiées ?Atténuation 3 | H51: =IF(F51='2. SAISIE DES DONNÉES'!$V$65,-1)+IF(F51='2. SAISIE DES DONNÉES'!$V$66,1) -> 0 | I51: =CONCATENATE(B51,F51) -> caféAtténuation 3 | J51: Mettre en œuvre des mesures de diversification des systèmes de production tels qu’une augmentation du nombre d’arbres fruitier, du bois d’œuvre et des cultures alimentaires
A52: Capacité d’adaptation | B52: thé | C52: Question 16 | D52: =CONCATENATE(B52,C52) -> théQuestion 16 | E52: Les pratiques agricoles ont-elles été associées en vue de compenser les vulnérabilités climatiques identifiées ? | F52: Atténuation 3 | G52: =CONCATENATE(E52,F52) -> Les pratiques agricoles ont-elles été associées en vue de compenser les vulnérabilités climatiques identifiées ?Atténuation 3 | H52: =IF(F52='2. SAISIE DES DONNÉES'!$V$65,-1)+IF(F52='2. SAISIE DES DONNÉES'!$V$66,1) -> 0 | I52: =CONCATENATE(B52,F52) -> théAtténuation 3 | J52: Mettre en œuvre des mesures de diversification des systèmes de production tels qu’une augmentation du nombre d’arbres fruitier, du bois d’œuvre et des cultures alimentaires
A53: Capacité d’adaptation | B53: les bananes | C53: Question 16 | D53: =CONCATENATE(B53,C53) -> les bananesQuestion 16 | E53: Les pratiques agricoles ont-elles été associées en vue de compenser les vulnérabilités climatiques identifiées ? | F53: Atténuation 3 | G53: =CONCATENATE(E53,F53) -> Les pratiques agricoles ont-elles été associées en vue de compenser les vulnérabilités climatiques identifiées ?Atténuation 3 | H53: =IF(F53='2. SAISIE DES DONNÉES'!$V$65,-1)+IF(F53='2. SAISIE DES DONNÉES'!$V$66,1) -> 0 | I53: =CONCATENATE(B53,F53) -> les bananesAtténuation 3 | J53: La diversification est un aspect clé de la résilience. Maintenir la diversification de la composition des espèces sur l’exploitation.
...

Sheet Data Sheet Current Vulnerabilit
A1: Niveau | B1: Produit agricole | C1: Question | D1: Concate1 | E1: Question (Consultation 1) | F1: Réponse | G1: Concate2 | H1: Réponse (Consultation 2) | I1: Concat3 | J1: Action d’atténuation (Consultation 3)
A2: Exposition | B2: cacao | C2: Question 1 | D2: =CONCATENATE(B2,C2) -> cacaoQuestion 1 | E2: La température a-t-elle changé au cours des 10 dernières années ? | F2: oui | G2: =CONCATENATE(E2,F2) -> La température a-t-elle changé au cours des 10 dernières années ? oui | H2: =IF(F2='2. SAISIE DES DONNÉES'!$V$65,-1)+IF(F2='2. SAISIE DES DONNÉES'!$V$66,1) -> -1 | R2: Produit agricole
A3: Exposition | B3: cacao | C3: Question 1 | D3: =CONCATENATE(B3,C3) -> cacaoQuestion 1 | E3: La température a-t-elle changé au cours des 10 dernières années ? | F3: non | G3: =CONCATENATE(E3,F3) -> La température a-t-elle changé au cours des 10 dernières années ? non | H3: =IF(F3='2. SAISIE DES DONNÉES'!$V$65,-1)+IF(F3='2. SAISIE DES DONNÉES'!$V$66,1) -> 1 | R3: Général
A4: Exposition | B4: café | C4: Question 1 | D4: =CONCATENATE(B4,C4) -> caféQuestion 1 | E4: La température a-t-elle changé au cours des 10 dernières années ? | F4: oui | G4: =CONCATENATE(E4,F4) -> La température a-t-elle changé au cours des 10 dernières années ? oui | H4: =IF(F4='2. SAISIE DES DONNÉES'!$V$65,-1)+IF(F4='2. SAISIE DES DONNÉES'!$V$66,1) -> -1 | R4: les bananes
A5: Exposition | B5: café | C5: Question 1 | D5: =CONCATENATE(B5,C5) -> caféQuestion 1 | E5: La température a-t-elle changé au cours des 10 dernières années ? | F5: non | G5: =CONCATENATE(E5,F5) -> La température a-t-elle changé au cours des 10 dernières années ? non | H5: =IF(F5='2. SAISIE DES DONNÉES'!$V$65,-1)+IF(F5='2. SAISIE DES DONNÉES'!$V$66,1) -> 1 | R5: cacao
A6: Exposition | B6: thé | C6: Question 1 | D6: =CONCATENATE(B6,C6) -> théQuestion 1 | E6: La température a-t-elle changé au cours des 10 dernières années ? | F6: oui | G6: =CONCATENATE(E6,F6) -> La température a-t-elle changé au cours des 10 dernières années ? oui | H6: =IF(F6='2. SAISIE DES DONNÉES'!$V$65,-1)+IF(F6='2. SAISIE DES DONNÉES'!$V$66,1) -> -1 | R6: café
A7: Exposition | B7: thé | C7: Question 1 | D7: =CONCATENATE(B7,C7) -> théQuestion 1 | E7: La température a-t-elle changé au cours des 10 dernières années ? | F7: non | G7: =CONCATENATE(E7,F7) -> La température a-t-elle changé au cours des 10 dernières années ? non | H7: =IF(F7='2. SAISIE DES DONNÉES'!$V$65,-1)+IF(F7='2. SAISIE DES DONNÉES'!$V$66,1) -> 1 | R7: thé
A8: Exposition | B8: les bananes | C8: Question 1 | D8: =CONCATENATE(B8,C8) -> les bananesQuestion 1 | E8: La température a-t-elle changé au cours des 10 dernières années ? | F8: oui | G8: =CONCATENATE(E8,F8) -> La température a-t-elle changé au cours des 10 dernières années ? oui | H8: =IF(F8='2. SAISIE DES DONNÉES'!$V$65,-1)+IF(F8='2. SAISIE DES DONNÉES'!$V$66,1) -> -1
A9: Exposition | B9: les bananes | C9: Question 1 | D9: =CONCATENATE(B9,C9) -> les bananesQuestion 1 | E9: La température a-t-elle changé au cours des 10 dernières années ? | F9: non | G9: =CONCATENATE(E9,F9) -> La température a-t-elle changé au cours des 10 dernières années ? non | H9: =IF(F9='2. SAISIE DES DONNÉES'!$V$65,-1)+IF(F9='2. SAISIE DES DONNÉES'!$V$66,1) -> 1
A10: Impacts | B10: cacao | C10: Question 10 | D10: =CONCATENATE(B10,C10) -> cacaoQuestion 10 | E10: Constatez-vous une augmentation de la chute des fleurs et des fruits ? | F10: oui | G10: =CONCATENATE(E10,F10) -> Constatez-vous une augmentation de la chute des fleurs et des fruits ? oui | H10: =IF(F10='2. SAISIE DES DONNÉES'!$V$65,-1)+IF(F10='2. SAISIE DES DONNÉES'!$V$66,1) -> -1
A11: Impacts | B11: cacao | C11: Question 10 | D11: =CONCATENATE(B11,C11) -> cacaoQuestion 10 | E11: Constatez-vous une augmentation de la chute des fleurs et des fruits ? | F11: non | G11: =CONCATENATE(E11,F11) -> Constatez-vous une augmentation de la chute des fleurs et des fruits ? non | H11: =IF(F11='2. SAISIE DES DONNÉES'!$V$65,-1)+IF(F11='2. SAISIE DES DONNÉES'!$V$66,1) -> 1
A12: Impacts | B12: café | C12: Question 10 | D12: =CONCATENATE(B12,C12) -> caféQuestion 10 | E12: Constatez-vous une augmentation de la chute des fleurs et des fruits ? | F12: oui | G12: =CONCATENATE(E12,F12) -> Constatez-vous une augmentation de la chute des fleurs et des fruits ? oui | H12: =IF(F12='2. SAISIE DES DONNÉES'!$V$65,-1)+IF(F12='2. SAISIE DES DONNÉES'!$V$66,1) -> -1
A13: Impacts | B13: café | C13: Question 10 | D13: =CONCATENATE(B13,C13) -> caféQuestion 10 | E13: Constatez-vous une augmentation de la chute des fleurs et des fruits ? | F13: non | G13: =CONCATENATE(E13,F13) -> Constatez-vous une augmentation de la chute des fleurs et des fruits ? non | H13: =IF(F13='2. SAISIE DES DONNÉES'!$V$65,-1)+IF(F13='2. SAISIE DES DONNÉES'!$V$66,1) -> 1
A14: Impacts | B14: thé | C14: Question 10 | D14: =CONCATENATE(B14,C14) -> théQuestion 10 | E14: Constatez-vous une augmentation de la chute des fleurs et des fruits ? | F14: oui | G14: =CONCATENATE(E14,F14) -> Constatez-vous une augmentation de la chute des fleurs et des fruits ? oui | H14: =IF(F14='2. SAISIE DES DONNÉES'!$V$65,-1)+IF(F14='2. SAISIE DES DONNÉES'!$V$66,1) -> -1
A15: Impacts | B15: thé | C15: Question 10 | D15: =CONCATENATE(B15,C15) -> théQuestion 10 | E15: Constatez-vous une augmentation de la chute des fleurs et des fruits ? | F15: non | G15: =CONCATENATE(E15,F15) -> Constatez-vous une augmentation de la chute des fleurs et des fruits ? non | H15: =IF(F15='2. SAISIE DES DONNÉES'!$V$65,-1)+IF(F15='2. SAISIE DES DONNÉES'!$V$66,1) -> 1
A16: Impacts | B16: les bananes | C16: Question 10 | D16: =CONCATENATE(B16,C16) -> les bananesQuestion 10 | E16: Constatez-vous une augmentation de la chute des fleurs et des fruits ? | F16: oui | G16: =CONCATENATE(E16,F16) -> Constatez-vous une augmentation de la chute des fleurs et des fruits ? oui | H16: =IF(F16='2. SAISIE DES DONNÉES'!$V$65,-1)+IF(F16='2. SAISIE DES DONNÉES'!$V$66,1) -> -1
A17: Impacts | B17: les bananes | C17: Question 10 | D17: =CONCATENATE(B17,C17) -> les bananesQuestion 10 | E17: Constatez-vous une augmentation de la chute des fleurs et des fruits ? | F17: non | G17: =CONCATENATE(E17,F17) -> Constatez-vous une augmentation de la chute des fleurs et des fruits ? non | H17: =IF(F17='2. SAISIE DES DONNÉES'!$V$65,-1)+IF(F17='2. SAISIE DES DONNÉES'!$V$66,1) -> 1
A18: Impacts | B18: cacao | C18: Question 11 | D18: =CONCATENATE(B18,C18) -> cacaoQuestion 11 | E18: Constatez-vous une augmentation de la défoliation des plantes (chute naturelle des feuilles) ? | F18: oui | G18: =CONCATENATE(E18,F18) -> Constatez-vous une augmentation de la défoliation des plantes (chute naturelle des feuilles) ?oui | H18: =IF(F18='2. SAISIE DES DONNÉES'!$V$65,-1)+IF(F18='2. SAISIE DES DONNÉES'!$V$66,1) -> -1
A19: Impacts | B19: cacao | C19: Question 11 | D19: =CONCATENATE(B19,C19) -> cacaoQuestion 11 | E19: Constatez-vous une augmentation de la défoliation des plantes (chute naturelle des feuilles) ? | F19: non | G19: =CONCATENATE(E19,F19) -> Constatez-vous une augmentation de la défoliation des plantes (chute naturelle des feuilles) ?non | H19: =IF(F19='2. SAISIE DES DONNÉES'!$V$65,-1)+IF(F19='2. SAISIE DES DONNÉES'!$V$66,1) -> 1
... A27: Impacts | B27: cacao | C27: Question 12 | D27: =CONCATENATE(B27,C27) -> cacaoQuestion 12 | E27: Les dégâts des ravageurs et des maladies sur le système de production ont-ils augmenté au cours des 5 à 10 dernières années (sur l’exploitation agricole) ? | F27: non | G27: =CONCATENATE(E27,F27) -> Les dégâts des ravageurs et des maladies sur le système de production ont-ils augmenté au cours des 5 à 10 dernières années (sur l’exploitation agricole) ? non | H27: =IF(F27='2. SAISIE DES DONNÉES'!$V$65,-1)+IF(F27='2. SAISIE DES DONNÉES'!$V$66,1) -> 1
A28: Impacts | B28: café | C28: Question 12 | D28: =CONCATENATE(B28,C28) -> caféQuestion 12 | E28: Les dégâts des ravageurs et des maladies sur le système de production ont-ils augmenté au cours des 5 à 10 dernières années (sur l’exploitation agricole) ? | F28: oui | G28: =CONCATENATE(E28,F28) -> Les dégâts des ravageurs et des maladies sur le système de production ont-ils augmenté au cours des 5 à 10 dernières années (sur l’exploitation agricole) ? oui | H28: =IF(F28='2. SAISIE DES DONNÉES'!$V$65,-1)+IF(F28='2. SAISIE DES DONNÉES'!$V$66,1) -> -1 | I28: =CONCATENATE(B28,F28) -> caféoui | J28: Sur la base de l’évaluation des sols, identifier les zones exposées aux risques d’érosion et mettre en place des pratiques de conservation des sols telles que terrasses, terrasses individuelles, conservation des sols, etc.
A29: Impacts | B29: café | C29: Question 12 | D29: =CONCATENATE(B29,C29) -> caféQuestion 12 | E29: Les dégâts des ravageurs et des maladies sur le système de production ont-ils augmenté au cours des 5 à 10 dernières années (sur l’exploitation agricole) ? | F29: non | G29: =CONCATENATE(E29,F29) -> Les dégâts des ravageurs et des maladies sur le système de production ont-ils augmenté au cours des 5 à 10 dernières années (sur l’exploitation agricole) ? non | H29: =IF(F29='2. SAISIE DES DONNÉES'!$V$65,-1)+IF(F29='2. SAISIE DES DONNÉES'!$V$66,1) -> 1 | I29: =CONCATENATE(B29,F29) -> cafénon | J29: Le sol de la zone de production n’est pas laissé à nu, il est protégé par des mesures telles que des cultures de couverture et du paillis afin de limiter l’érosion et la perte de nutriments au profit de l’augmentation des nutriments et de la ressource en eau
A30: Impacts | B30: thé | C30: Question 12 | D30: =CONCATENATE(B30,C30) -> théQuestion 12 | E30: Les dégâts des ravageurs et des maladies sur le système de production ont-ils augmenté au cours des 5 à 10 dernières années (sur l’exploitation agricole) ? | F30: oui | G30: =CONCATENATE(E30,F30) -> Les dégâts des ravageurs et des maladies sur le système de production ont-ils augmenté au cours des 5 à 10 dernières années (sur l’exploitation agricole) ? oui | H30: =IF(F30='2. SAISIE DES DONNÉES'!$V$65,-1)+IF(F30='2. SAISIE DES DONNÉES'!$V$66,1) -> -1 | I30: =CONCATENATE(B30,F30) -> théoui | J30: Mettre en œuvre des mesures de diversification des systèmes de production tels qu’une augmentation du nombre d’arbres fruitier, du bois d’œuvre et des cultures alimentaires
A31: Impacts | B31: thé | C31: Question 12 | D31: =CONCATENATE(B31,C31) -> théQuestion 12 | E31: Les dégâts des ravageurs et des maladies sur le système de production ont-ils augmenté au cours des 5 à 10 dernières années (sur l’exploitation agricole) ? | F31: non | G31: =CONCATENATE(E31,F31) -> Les dégâts des ravageurs et des maladies sur le système de production ont-ils augmenté au cours des 5 à 10 dernières années (sur l’exploitation agricole) ? non | H31: =IF(F31='2. SAISIE DES DONNÉES'!$V$65,-1)+IF(F31='2. SAISIE DES DONNÉES'!$V$66,1) -> 1 | I31: =CONCATENATE(B31,F31) -> thénon | J31: Si les systèmes de production sont exposés en plein soleil, essayer de renforcer l’ombrage jusqu’au seuil optimal de couverture. En cas d’ombrage excessif, mettre en œuvre des activités de gestion de l’ombre permettant d’atteindre le seuil optimal
A32: Impacts | B32: les bananes | C32: Question 12 | D32: =CONCATENATE(B32,C32) -> les bananesQuestion 12 | E32: Les dégâts des ravageurs et des maladies sur le système de production ont-ils augmenté au cours des 5 à 10 dernières années (sur l’exploitation agricole) ? | F32: oui | G32: =CONCATENATE(E32,F32) -> Les dégâts des ravageurs et des maladies sur le système de production ont-ils augmenté au cours des 5 à 10 dernières années (sur l’exploitation agricole) ? oui | H32: =IF(F32='2. SAISIE DES DONNÉES'!$V$65,-1)+IF(F32='2. SAISIE DES DONNÉES'!$V$66,1) -> -1 | I32: =CONCATENATE(B32,F32) -> les bananesoui | J32: Mettre en œuvre une taille ou un élagage progressif de rajeunissement ou la plantation progressive de nouvelles plantes. Sélectionner les nouveaux plants en fonction des conditions climatiques futures.
A33: Impacts | B33: les bananes | C33: Question 12 | D33: =CONCATENATE(B33,C33) -> les bananesQuestion 12 | E33: Les dégâts des ravageurs et des maladies sur le système de production ont-ils augmenté au cours des 5 à 10 dernières années (sur l’exploitation agricole) ? | F33: non | G33: =CONCATENATE(E33,F33) -> Les dégâts des ravageurs et des maladies sur le système de production ont-ils augmenté au cours des 5 à 10 dernières années (sur l’exploitation agricole) ? non | H33: =IF(F33='2. SAISIE DES DONNÉES'!$V$65,-1)+IF(F33='2. SAISIE DES DONNÉES'!$V$66,1) -> 1 | I33: =CONCATENATE(B33,F33) -> les bananesnon | J33: Améliorer la surveillance des ravageurs et des maladies afin d’en évaluer les impacts sur les cacaoyers
A34: Impacts | B34: cacao | C34: Question 13 | D34: =CONCATENATE(B34,C34) -> cacaoQuestion 13 | E34: La productivité a-t-elle diminué au cours des dernières années (5 à 10 ans) en raison du changement climatique ? | F34: oui | G34: =CONCATENATE(E34,F34) -> La productivité a-t-elle diminué au cours des dernières années (5 à 10 ans) en raison du changement climatique ? oui | H34: =IF(F34='2. SAISIE DES DONNÉES'!$V$65,-1)+IF(F34='2. SAISIE DES DONNÉES'!$V$66,1) -> -1 | I34: =CONCATENATE(B34,F34) -> cacaooui | J34: Maintenir les pratiques de taille et d’élagage
A35: Impacts | B35: cacao | C35: Question 13 | D35: =CONCATENATE(B35,C35) -> cacaoQuestion 13 | E35: La productivité a-t-elle diminué au cours des dernières années (5 à 10 ans) en raison du changement climatique ? | F35: non | G35: =CONCATENATE(E35,F35) -> La productivité a-t-elle diminué au cours des dernières années (5 à 10 ans) en raison du changement climatique ? non | H35: =IF(F35='2. SAISIE DES DONNÉES'!$V$65,-1)+IF(F35='2. SAISIE DES DONNÉES'!$V$66,1) -> 1 | I35: =CONCATENATE(B35,F35) -> cacaonon | J35: Replanter les plantes malades conformément à la stratégie de LIR
A36: Impacts | B36: café | C36: Question 13 | D36: =CONCATENATE(B36,C36) -> caféQuestion 13 | E36: La productivité a-t-elle diminué au cours des dernières années (5 à 10 ans) en raison du changement climatique ? | F36: oui | G36: =CONCATENATE(E36,F36) -> La productivité a-t-elle diminué au cours des dernières années (5 à 10 ans) en raison du changement climatique ? oui | H36: =IF(F36='2. SAISIE DES DONNÉES'!$V$65,-1)+IF(F36='2. SAISIE DES DONNÉES'!$V$66,1) -> -1 | I36: =CONCATENATE(B36,F36) -> caféoui | J36: Épandre en premier lieu les engrais biologiques et les sous-produits disponibles sur l’exploitation, puis compléter avec des engrais chimiques si les nutriments restent insuffisants.
